Qubicle Exchange Format
Version 0.2
www.minddesk.com
8 8 8
10
0.078431 0.070588 0.117647
0.152941 0.262745 0.541176
0.184314 0.435294 0.537255
0.235294 0.341176 0.294118
0.258824 0.682353 0.223529
0.368627 0.529412 0.482353
0.419608 0.666667 0.592157
0.498039 0.243137 0.713726
0.521569 0.576471 1.000000
0.670588 0.109804 0.035294
0 0 0 0 84
0 0 1 3 22
0 0 2 6 22
0 0 3 6 22
0 0 4 6 22
0 0 5 6 22
0 0 6 3 22
0 0 7 1 52
0 1 0 3 68
0 1 1 5 6
0 1 2 5 6
0 1 3 5 6
0 1 4 5 6
0 1 5 5 6
0 1 6 5 6
0 1 7 3 38
0 2 0 6 68
0 2 1 6 4
0 2 2 6 4
0 2 3 6 4
0 2 4 6 4
0 2 5 6 4
0 2 6 6 4
0 2 7 6 36
0 3 0 5 68
0 3 1 5 4
0 3 2 5 4
0 3 3 9 4
0 3 4 9 4
0 3 5 5 4
0 3 6 5 4
0 3 7 5 36
0 4 0 6 68
0 4 1 6 4
0 4 2 6 4
0 4 3 9 4
0 4 4 6 4
0 4 5 6 4
0 4 6 6 4
0 4 7 6 36
0 5 0 5 68
0 5 1 5 4
0 5 2 5 4
0 5 3 9 4
0 5 4 9 4
0 5 5 5 4
0 5 6 5 4
0 5 7 5 36
0 6 0 3 68
0 6 1 6 4
0 6 2 6 4
0 6 3 9 4
0 6 4 9 4
0 6 5 6 4
0 6 6 6 4
0 6 7 3 36
0 7 0 8 76
0 7 1 3 12
0 7 2 5 12
0 7 3 5 12
0 7 4 5 12
0 7 5 5 12
0 7 6 3 12
0 7 7 2 44
1 0 0 3 112
1 0 1 5 126
1 0 2 5 126
1 0 3 5 126
1 0 4 5 126
1 0 5 5 126
1 0 6 5 126
1 0 7 3 120
1 1 0 5 96
1 1 1 5 126
1 1 2 5 126
1 1 3 5 126
1 1 4 5 126
1 1 5 5 126
1 1 6 5 126
1 1 7 5 126
1 2 0 6 64
1 2 1 5 16
1 2 2 5 16
1 2 3 5 16
1 2 4 5 16
1 2 5 5 16
1 2 6 5 16
1 2 7 6 48
1 3 0 5 64
1 3 1 6 0
1 3 2 6 0
1 3 3 6 0
1 3 4 6 0
1 3 5 6 0
1 3 6 6 0
1 3 7 5 32
1 4 0 6 64
1 4 1 6 0
1 4 2 6 0
1 4 3 6 0
1 4 4 6 0
1 4 5 6 0
1 4 6 6 0
1 4 7 6 32
1 5 0 5 64
1 5 1 6 0
1 5 2 6 0
1 5 3 6 0
1 5 4 6 0
1 5 5 6 0
1 5 6 6 0
1 5 7 5 32
1 6 0 6 64
1 6 1 6 0
1 6 2 6 0
1 6 3 6 0
1 6 4 6 0
1 6 5 6 0
1 6 6 6 0
1 6 7 6 32
1 7 0 3 72
1 7 1 6 8
1 7 2 6 8
1 7 3 6 8
1 7 4 6 8
1 7 5 6 8
1 7 6 6 8
1 7 7 3 40
2 0 0 6 112
2 0 1 5 126
2 0 2 6 126
2 0 3 6 126
2 0 4 6 126
2 0 5 6 126
2 0 6 5 126
2 0 7 6 120
2 1 0 5 96
2 1 1 5 126
2 1 2 5 126
2 1 3 5 126
2 1 4 5 126
2 1 5 5 126
2 1 6 5 126
2 1 7 5 126
2 2 0 6 64
2 2 1 5 16
2 2 2 6 16
2 2 3 6 16
2 2 4 6 16
2 2 5 6 16
2 2 6 5 16
2 2 7 6 48
2 3 0 5 64
2 3 1 6 0
2 3 2 6 0
2 3 3 6 0
2 3 4 6 0
2 3 5 6 0
2 3 6 6 0
2 3 7 5 32
2 4 0 6 64
2 4 1 6 0
2 4 2 6 0
2 4 3 6 0
2 4 4 6 0
2 4 5 6 0
2 4 6 6 0
2 4 7 6 32
2 5 0 5 64
2 5 1 6 0
2 5 2 6 0
2 5 3 6 0
2 5 4 6 0
2 5 5 6 0
2 5 6 6 0
2 5 7 5 32
2 6 0 6 64
2 6 1 6 0
2 6 2 6 0
2 6 3 6 0
2 6 4 6 0
2 6 5 6 0
2 6 6 6 0
2 6 7 6 32
2 7 0 5 72
2 7 1 6 8
2 7 2 9 8
2 7 3 5 8
2 7 4 5 8
2 7 5 5 8
2 7 6 6 8
2 7 7 5 40
3 0 0 6 112
3 0 1 5 126
3 0 2 6 126
3 0 3 5 126
3 0 4 5 126
3 0 5 6 126
3 0 6 5 126
3 0 7 6 120
3 1 0 5 96
3 1 1 5 126
3 1 2 5 126
3 1 3 5 126
3 1 4 5 126
3 1 5 5 126
3 1 6 5 126
3 1 7 5 126
3 2 0 6 64
3 2 1 5 16
3 2 2 6 16
3 2 3 5 16
3 2 4 5 16
3 2 5 6 16
3 2 6 5 16
3 2 7 6 48
3 3 0 9 64
3 3 1 6 0
3 3 2 6 0
3 3 3 6 0
3 3 4 6 0
3 3 5 6 0
3 3 6 6 0
3 3 7 9 32
3 4 0 9 64
3 4 1 6 0
3 4 2 6 0
3 4 3 6 0
3 4 4 6 0
3 4 5 6 0
3 4 6 6 0
3 4 7 9 32
3 5 0 9 64
3 5 1 6 0
3 5 2 6 0
3 5 3 6 0
3 5 4 6 0
3 5 5 6 0
3 5 6 6 0
3 5 7 9 32
3 6 0 6 64
3 6 1 6 0
3 6 2 6 0
3 6 3 6 0
3 6 4 6 0
3 6 5 6 0
3 6 6 6 0
3 6 7 9 32
3 7 0 5 72
3 7 1 6 8
3 7 2 9 8
3 7 3 9 8
3 7 4 9 8
3 7 5 9 8
3 7 6 6 8
3 7 7 5 40
4 0 0 6 112
4 0 1 5 126
4 0 2 6 126
4 0 3 5 126
4 0 4 5 126
4 0 5 6 126
4 0 6 5 126
4 0 7 6 120
4 1 0 5 96
4 1 1 5 126
4 1 2 5 126
4 1 3 5 126
4 1 4 5 126
4 1 5 5 126
4 1 6 5 126
4 1 7 5 126
4 2 0 6 64
4 2 1 5 16
4 2 2 6 16
4 2 3 5 16
4 2 4 5 16
4 2 5 6 16
4 2 6 5 16
4 2 7 6 48
4 3 0 9 64
4 3 1 6 0
4 3 2 6 0
4 3 3 6 0
4 3 4 6 0
4 3 5 6 0
4 3 6 6 0
4 3 7 5 32
4 4 0 9 64
4 4 1 6 0
4 4 2 6 0
4 4 3 6 0
4 4 4 6 0
4 4 5 6 0
4 4 6 6 0
4 4 7 9 32
4 5 0 9 64
4 5 1 6 0
4 5 2 6 0
4 5 3 6 0
4 5 4 6 0
4 5 5 6 0
4 5 6 6 0
4 5 7 5 32
4 6 0 9 64
4 6 1 6 0
4 6 2 6 0
4 6 3 6 0
4 6 4 6 0
4 6 5 6 0
4 6 6 6 0
4 6 7 9 32
4 7 0 5 72
4 7 1 6 8
4 7 2 9 8
4 7 3 6 8
4 7 4 6 8
4 7 5 5 8
4 7 6 6 8
4 7 7 5 40
5 0 0 6 112
5 0 1 5 126
5 0 2 6 126
5 0 3 6 126
5 0 4 6 126
5 0 5 6 126
5 0 6 5 126
5 0 7 6 120
5 1 0 5 96
5 1 1 5 126
5 1 2 5 126
5 1 3 5 126
5 1 4 5 126
5 1 5 5 126
5 1 6 5 126
5 1 7 5 126
5 2 0 6 64
5 2 1 5 16
5 2 2 6 16
5 2 3 6 16
5 2 4 6 16
5 2 5 6 16
5 2 6 5 16
5 2 7 6 48
5 3 0 5 64
5 3 1 6 0
5 3 2 6 0
5 3 3 6 0
5 3 4 6 0
5 3 5 6 0
5 3 6 6 0
5 3 7 5 32
5 4 0 6 64
5 4 1 6 0
5 4 2 6 0
5 4 3 6 0
5 4 4 6 0
5 4 5 6 0
5 4 6 6 0
5 4 7 6 32
5 5 0 5 64
5 5 1 6 0
5 5 2 6 0
5 5 3 6 0
5 5 4 6 0
5 5 5 6 0
5 5 6 6 0
5 5 7 5 32
5 6 0 6 64
5 6 1 6 0
5 6 2 6 0
5 6 3 6 0
5 6 4 6 0
5 6 5 6 0
5 6 6 6 0
5 6 7 6 32
5 7 0 5 72
5 7 1 6 8
5 7 2 5 8
5 7 3 5 8
5 7 4 5 8
5 7 5 5 8
5 7 6 6 8
5 7 7 5 40
6 0 0 3 112
6 0 1 5 126
6 0 2 5 126
6 0 3 5 126
6 0 4 5 126
6 0 5 5 126
6 0 6 5 126
6 0 7 3 126
6 1 0 5 96
6 1 1 5 126
6 1 2 5 126
6 1 3 5 126
6 1 4 5 126
6 1 5 5 126
6 1 6 5 126
6 1 7 5 126
6 2 0 6 64
6 2 1 5 16
6 2 2 5 16
6 2 3 5 16
6 2 4 5 16
6 2 5 5 16
6 2 6 5 16
6 2 7 6 48
6 3 0 5 64
6 3 1 6 0
6 3 2 6 0
6 3 3 6 0
6 3 4 6 0
6 3 5 6 0
6 3 6 6 0
6 3 7 5 32
6 4 0 6 64
6 4 1 6 0
6 4 2 6 0
6 4 3 6 0
6 4 4 6 0
6 4 5 6 0
6 4 6 6 0
6 4 7 6 32
6 5 0 5 64
6 5 1 6 0
6 5 2 6 0
6 5 3 6 0
6 5 4 6 0
6 5 5 6 0
6 5 6 6 0
6 5 7 5 32
6 6 0 6 64
6 6 1 6 0
6 6 2 6 0
6 6 3 6 0
6 6 4 6 0
6 6 5 6 0
6 6 6 6 0
6 6 7 6 32
6 7 0 3 72
6 7 1 6 8
6 7 2 6 8
6 7 3 6 8
6 7 4 6 8
6 7 5 6 8
6 7 6 6 8
6 7 7 3 40
7 0 0 1 82
7 0 1 3 30
7 0 2 6 30
7 0 3 6 30
7 0 4 6 30
7 0 5 6 30
7 0 6 3 126
7 0 7 7 58
7 1 0 3 98
7 1 1 5 126
7 1 2 5 126
7 1 3 5 126
7 1 4 5 126
7 1 5 5 126
7 1 6 5 126
7 1 7 3 126
7 2 0 6 66
7 2 1 6 18
7 2 2 6 18
7 2 3 6 18
7 2 4 6 18
7 2 5 6 18
7 2 6 6 18
7 2 7 6 50
7 3 0 5 66
7 3 1 5 2
7 3 2 5 2
7 3 3 9 2
7 3 4 9 2
7 3 5 5 2
7 3 6 5 2
7 3 7 5 34
7 4 0 6 66
7 4 1 6 2
7 4 2 6 2
7 4 3 6 2
7 4 4 9 2
7 4 5 6 2
7 4 6 6 2
7 4 7 6 34
7 5 0 5 66
7 5 1 5 2
7 5 2 5 2
7 5 3 5 2
7 5 4 9 2
7 5 5 5 2
7 5 6 5 2
7 5 7 5 34
7 6 0 3 66
7 6 1 6 2
7 6 2 6 2
7 6 3 6 2
7 6 4 9 2
7 6 5 6 2
7 6 6 6 2
7 6 7 3 34
7 7 0 2 74
7 7 1 3 10
7 7 2 5 10
7 7 3 5 10
7 7 4 5 10
7 7 5 5 10
7 7 6 3 10
7 7 7 4 42
