Qubicle Exchange Format
Version 0.2
www.minddesk.com
100 15 43
8
0.9764705882352941 0.9254901960784314 0.3058823529411765
0.7294117647058823 0.5215686274509804 0.13725490196078433
0.2235294117647059 0.16470588235294117 0.13725490196078433
0.30196078431372547 0.2 0.13725490196078433
0.5882352941176471 0.20392156862745098 0.18823529411764706
0.6039215686274509 0.6313725490196078 0.6313725490196078
0.8666666666666667 0.8666666666666667 0.8666666666666667
0.25098039215686274 0.25098039215686274 0.25098039215686274
0 7 21 0
1 6 21 1
1 7 20 1
1 7 21 0
1 7 22 0
1 8 21 1
2 5 21 0
2 6 19 0
2 6 20 0
2 6 21 0
2 6 22 1
2 6 23 0
2 7 19 1
2 7 20 0
2 7 21 0
2 7 22 0
2 7 23 1
2 8 19 0
2 8 20 0
2 8 21 0
2 8 22 1
2 8 23 0
2 9 21 0
3 4 20 0
3 4 21 1
3 4 22 0
3 5 19 0
3 5 20 1
3 5 21 0
3 5 22 0
3 5 23 1
3 6 19 1
3 6 20 0
3 6 21 0
3 6 22 0
3 6 23 0
3 7 18 0
3 7 19 0
3 7 20 0
3 7 21 0
3 7 22 0
3 7 23 0
3 7 24 0
3 8 19 1
3 8 20 0
3 8 21 0
3 8 22 0
3 8 23 0
3 9 19 0
3 9 20 1
3 9 21 0
3 9 22 0
3 9 23 1
3 10 20 0
3 10 21 1
3 10 22 0
4 3 21 0
4 4 19 0
4 4 20 0
4 4 21 0
4 4 22 0
4 4 23 0
4 5 18 0
4 5 19 0
4 5 20 0
4 5 21 0
4 5 22 0
4 5 23 0
4 5 24 0
4 6 17 0
4 6 18 1
4 6 19 0
4 6 20 0
4 6 21 0
4 6 22 0
4 6 23 0
4 6 24 1
4 6 25 0
4 7 16 0
4 7 17 0
4 7 18 0
4 7 19 0
4 7 20 0
4 7 21 0
4 7 22 0
4 7 23 0
4 7 24 0
4 7 25 0
4 7 26 0
4 8 17 0
4 8 18 1
4 8 19 0
4 8 20 0
4 8 21 0
4 8 22 0
4 8 23 0
4 8 24 1
4 8 25 0
4 9 18 0
4 9 19 0
4 9 20 0
4 9 21 0
4 9 22 0
4 9 23 0
4 9 24 0
4 10 19 0
4 10 20 0
4 10 21 0
4 10 22 0
4 10 23 0
4 11 21 0
5 2 20 0
5 2 21 0
5 2 22 0
5 3 19 0
5 3 20 0
5 3 21 0
5 3 22 0
5 3 23 0
5 4 18 0
5 4 19 0
5 4 20 0
5 4 21 0
5 4 22 0
5 4 23 0
5 4 24 0
5 5 17 0
5 5 18 0
5 5 19 0
5 5 20 0
5 5 21 0
5 5 22 0
5 5 23 0
5 5 24 0
5 5 25 0
5 6 16 0
5 6 17 0
5 6 18 0
5 6 19 0
5 6 20 0
5 6 23 0
5 6 24 0
5 6 25 0
5 6 26 0
5 7 16 0
5 7 17 0
5 7 18 0
5 7 19 0
5 7 24 0
5 7 25 0
5 7 26 0
5 8 16 0
5 8 17 0
5 8 18 0
5 8 19 0
5 8 20 0
5 8 23 0
5 8 24 0
5 8 25 0
5 8 26 0
5 9 17 0
5 9 18 0
5 9 19 0
5 9 20 0
5 9 21 0
5 9 22 0
5 9 23 0
5 9 24 0
5 9 25 0
5 10 18 0
5 10 19 0
5 10 20 0
5 10 21 0
5 10 22 0
5 10 23 0
5 10 24 0
5 11 19 0
5 11 20 0
5 11 21 0
5 11 22 0
5 11 23 0
5 12 20 0
5 12 21 0
5 12 22 0
6 1 21 0
6 2 19 0
6 2 20 0
6 2 21 0
6 2 22 0
6 2 23 0
6 3 18 0
6 3 19 0
6 3 20 0
6 3 21 0
6 3 22 0
6 3 23 0
6 3 24 0
6 4 17 0
6 4 18 0
6 4 19 0
6 4 20 0
6 4 21 0
6 4 22 0
6 4 23 0
6 4 24 0
6 4 25 0
6 5 16 0
6 5 17 0
6 5 18 0
6 5 19 0
6 5 20 0
6 5 22 0
6 5 23 0
6 5 24 0
6 5 25 0
6 5 26 0
6 6 15 0
6 6 16 0
6 6 17 0
6 6 18 0
6 6 19 0
6 6 23 0
6 6 24 0
6 6 25 0
6 6 26 0
6 6 27 0
6 7 15 0
6 7 16 0
6 7 17 0
6 7 18 0
6 7 24 0
6 7 25 0
6 7 26 0
6 7 27 0
6 8 15 0
6 8 16 0
6 8 17 0
6 8 18 0
6 8 19 0
6 8 23 0
6 8 24 0
6 8 25 0
6 8 26 0
6 8 27 0
6 9 16 0
6 9 17 0
6 9 18 0
6 9 19 0
6 9 20 0
6 9 22 0
6 9 23 0
6 9 24 0
6 9 25 0
6 9 26 0
6 10 17 0
6 10 18 0
6 10 19 0
6 10 20 0
6 10 21 0
6 10 22 0
6 10 23 0
6 10 24 0
6 10 25 0
6 11 18 0
6 11 19 0
6 11 20 0
6 11 21 0
6 11 22 0
6 11 23 0
6 11 24 0
6 12 19 0
6 12 20 0
6 12 21 0
6 12 22 0
6 12 23 0
6 13 21 0
7 1 20 0
7 1 21 0
7 1 22 0
7 2 18 0
7 2 19 0
7 2 20 1
7 2 21 0
7 2 22 1
7 2 23 0
7 2 24 0
7 3 17 0
7 3 18 0
7 3 19 0
7 3 20 0
7 3 21 1
7 3 22 0
7 3 23 1
7 3 24 0
7 3 25 0
7 4 16 0
7 4 17 0
7 4 18 1
7 4 19 0
7 4 20 0
7 4 21 0
7 4 22 0
7 4 23 0
7 4 24 1
7 4 25 1
7 4 26 0
7 5 15 0
7 5 16 0
7 5 17 1
7 5 18 1
7 5 19 0
7 5 20 2
7 5 22 2
7 5 23 0
7 5 24 1
7 5 25 0
7 5 26 0
7 5 27 0
7 6 15 0
7 6 16 1
7 6 17 0
7 6 18 2
7 6 19 2
7 6 20 2
7 6 22 2
7 6 23 2
7 6 24 0
7 6 25 0
7 6 26 1
7 6 27 0
7 7 15 0
7 7 16 1
7 7 17 0
7 7 24 2
7 7 25 0
7 7 26 1
7 7 27 0
7 8 15 0
7 8 16 1
7 8 17 0
7 8 18 2
7 8 19 2
7 8 20 2
7 8 22 2
7 8 23 2
7 8 24 0
7 8 25 0
7 8 26 1
7 8 27 0
7 9 15 0
7 9 16 0
7 9 17 1
7 9 18 1
7 9 19 0
7 9 20 2
7 9 22 2
7 9 23 0
7 9 24 1
7 9 25 0
7 9 26 0
7 9 27 0
7 10 16 0
7 10 17 0
7 10 18 1
7 10 19 0
7 10 20 0
7 10 21 0
7 10 22 0
7 10 23 0
7 10 24 1
7 10 25 1
7 10 26 0
7 11 17 0
7 11 18 0
7 11 19 0
7 11 20 0
7 11 21 1
7 11 22 0
7 11 23 1
7 11 24 0
7 11 25 0
7 12 18 0
7 12 19 0
7 12 20 1
7 12 21 0
7 12 22 1
7 12 23 0
7 12 24 0
7 13 20 0
7 13 21 0
7 13 22 0
8 1 19 0
8 1 20 0
8 1 21 0
8 1 22 0
8 1 23 0
8 2 17 0
8 2 18 0
8 2 24 0
8 2 25 0
8 3 16 0
8 3 20 2
8 3 22 2
8 3 26 0
8 4 16 0
8 4 19 2
8 4 20 2
8 4 21 2
8 4 22 2
8 4 23 2
8 4 26 0
8 5 15 0
8 5 19 2
8 5 20 2
8 5 21 2
8 5 22 2
8 5 23 2
8 5 27 0
8 6 15 0
8 6 17 2
8 6 18 2
8 6 19 2
8 6 20 2
8 6 21 2
8 6 22 2
8 6 23 2
8 6 24 2
8 6 25 2
8 6 27 0
8 7 15 0
8 7 17 2
8 7 18 2
8 7 19 2
8 7 20 2
8 7 22 2
8 7 23 2
8 7 24 2
8 7 25 2
8 7 27 0
8 8 15 0
8 8 17 2
8 8 18 2
8 8 19 2
8 8 20 2
8 8 21 2
8 8 22 2
8 8 23 2
8 8 24 2
8 8 25 2
8 8 27 0
8 9 15 0
8 9 19 2
8 9 20 2
8 9 21 2
8 9 22 2
8 9 23 2
8 9 27 0
8 10 16 0
8 10 19 2
8 10 20 2
8 10 21 2
8 10 22 2
8 10 23 2
8 10 26 0
8 11 16 0
8 11 20 2
8 11 22 2
8 11 26 0
8 12 17 0
8 12 18 0
8 12 24 0
8 12 25 0
8 13 19 0
8 13 20 0
8 13 21 0
8 13 22 0
8 13 23 0
9 3 20 3
9 3 21 2
9 3 22 3
9 4 20 2
9 4 21 2
9 4 22 2
9 5 18 2
9 5 19 2
9 5 20 2
9 5 21 2
9 5 22 2
9 5 23 2
9 5 24 2
9 6 17 3
9 6 18 2
9 6 19 2
9 6 20 2
9 6 21 2
9 6 22 2
9 6 23 2
9 6 24 2
9 6 25 3
9 7 18 2
9 7 19 2
9 7 20 2
9 7 22 2
9 7 23 2
9 7 24 2
9 8 17 3
9 8 18 2
9 8 19 2
9 8 20 2
9 8 21 2
9 8 22 2
9 8 23 2
9 8 24 2
9 8 25 3
9 9 18 2
9 9 19 2
9 9 20 2
9 9 21 2
9 9 22 2
9 9 23 2
9 9 24 2
9 10 20 2
9 10 21 2
9 10 22 2
9 11 20 3
9 11 21 2
9 11 22 3
10 3 21 3
10 4 19 2
10 4 20 2
10 4 21 2
10 4 22 2
10 4 23 2
10 5 18 3
10 5 19 2
10 5 20 2
10 5 21 2
10 5 22 2
10 5 23 2
10 5 24 3
10 6 18 2
10 6 19 2
10 6 20 2
10 6 21 2
10 6 22 2
10 6 23 2
10 6 24 2
10 7 17 2
10 7 18 2
10 7 19 2
10 7 20 2
10 7 22 2
10 7 23 2
10 7 24 2
10 7 25 2
10 8 18 2
10 8 19 2
10 8 20 2
10 8 21 2
10 8 22 2
10 8 23 2
10 8 24 2
10 9 18 3
10 9 19 2
10 9 20 2
10 9 21 2
10 9 22 2
10 9 23 2
10 9 24 3
10 10 19 2
10 10 20 2
10 10 21 2
10 10 22 2
10 10 23 2
10 11 21 3
11 3 20 2
11 3 22 2
11 4 19 3
11 4 20 2
11 4 21 2
11 4 22 2
11 4 23 3
11 5 19 2
11 5 20 2
11 5 21 2
11 5 22 2
11 5 23 2
11 6 17 2
11 6 18 2
11 6 19 2
11 6 20 2
11 6 21 2
11 6 22 2
11 6 23 2
11 6 24 2
11 6 25 2
11 7 17 2
11 7 18 2
11 7 19 2
11 7 20 2
11 7 23 2
11 7 24 2
11 7 25 3
11 8 17 2
11 8 18 2
11 8 19 2
11 8 20 2
11 8 21 2
11 8 22 2
11 8 23 2
11 8 24 2
11 8 25 2
11 9 19 2
11 9 20 2
11 9 21 2
11 9 22 2
11 9 23 2
11 10 19 3
11 10 20 2
11 10 21 2
11 10 22 2
11 10 23 3
11 11 20 2
11 11 22 2
12 3 20 3
12 3 21 2
12 3 22 3
12 4 20 2
12 4 21 2
12 4 22 2
12 5 18 2
12 5 19 2
12 5 20 2
12 5 21 2
12 5 22 2
12 5 23 2
12 5 24 2
12 6 17 3
12 6 18 2
12 6 19 2
12 6 20 2
12 6 21 2
12 6 22 2
12 6 23 2
12 6 24 2
12 6 25 3
12 7 18 2
12 7 19 2
12 7 20 2
12 7 22 2
12 7 23 2
12 7 24 2
12 8 17 3
12 8 18 2
12 8 19 2
12 8 20 2
12 8 21 2
12 8 22 2
12 8 23 2
12 8 24 2
12 8 25 3
12 9 18 2
12 9 19 2
12 9 20 2
12 9 21 2
12 9 22 2
12 9 23 2
12 9 24 2
12 10 20 2
12 10 21 2
12 10 22 2
12 11 20 3
12 11 21 2
12 11 22 3
13 3 21 3
13 4 19 2
13 4 20 2
13 4 21 2
13 4 22 2
13 4 23 2
13 5 18 3
13 5 19 2
13 5 20 2
13 5 21 2
13 5 22 2
13 5 23 2
13 5 24 3
13 6 18 2
13 6 19 2
13 6 20 2
13 6 21 2
13 6 22 2
13 6 23 2
13 6 24 2
13 7 17 2
13 7 18 2
13 7 19 2
13 7 20 2
13 7 22 2
13 7 23 2
13 7 24 2
13 7 25 2
13 8 18 2
13 8 19 2
13 8 20 2
13 8 21 2
13 8 22 2
13 8 23 2
13 8 24 2
13 9 18 3
13 9 19 2
13 9 20 2
13 9 21 2
13 9 22 2
13 9 23 2
13 9 24 3
13 10 19 2
13 10 20 2
13 10 21 2
13 10 22 2
13 10 23 2
13 11 21 3
14 3 20 2
14 3 22 2
14 4 19 3
14 4 20 2
14 4 21 2
14 4 22 2
14 4 23 3
14 5 19 2
14 5 20 2
14 5 21 2
14 5 22 2
14 5 23 2
14 6 17 2
14 6 18 2
14 6 19 2
14 6 20 2
14 6 21 2
14 6 22 2
14 6 23 2
14 6 24 2
14 6 25 2
14 7 17 2
14 7 18 2
14 7 19 2
14 7 22 2
14 7 23 2
14 7 24 2
14 7 25 3
14 8 17 2
14 8 18 2
14 8 19 2
14 8 20 2
14 8 21 2
14 8 22 2
14 8 23 2
14 8 24 2
14 8 25 2
14 9 19 2
14 9 20 2
14 9 21 2
14 9 22 2
14 9 23 2
14 10 19 3
14 10 20 2
14 10 21 2
14 10 22 2
14 10 23 3
14 11 20 2
14 11 22 2
15 3 20 3
15 3 21 2
15 3 22 3
15 4 20 2
15 4 21 2
15 4 22 2
15 5 18 2
15 5 19 2
15 5 20 2
15 5 21 2
15 5 22 2
15 5 23 2
15 5 24 2
15 6 17 3
15 6 18 2
15 6 19 2
15 6 20 2
15 6 21 2
15 6 22 2
15 6 23 2
15 6 24 2
15 6 25 3
15 7 18 2
15 7 19 2
15 7 22 2
15 7 23 2
15 7 24 2
15 8 17 3
15 8 18 2
15 8 19 2
15 8 20 2
15 8 21 2
15 8 22 2
15 8 23 2
15 8 24 2
15 8 25 3
15 9 18 2
15 9 19 2
15 9 20 2
15 9 21 2
15 9 22 2
15 9 23 2
15 9 24 2
15 10 20 2
15 10 21 2
15 10 22 2
15 11 20 3
15 11 21 2
15 11 22 3
16 3 21 3
16 4 19 2
16 4 20 2
16 4 21 2
16 4 22 2
16 4 23 2
16 5 18 3
16 5 19 2
16 5 20 2
16 5 21 2
16 5 22 2
16 5 23 2
16 5 24 3
16 6 18 2
16 6 19 2
16 6 20 2
16 6 21 2
16 6 22 2
16 6 23 2
16 6 24 2
16 7 17 2
16 7 18 2
16 7 19 2
16 7 20 2
16 7 22 2
16 7 23 2
16 7 24 2
16 7 25 2
16 8 18 2
16 8 19 2
16 8 20 2
16 8 21 2
16 8 22 2
16 8 23 2
16 8 24 2
16 9 18 3
16 9 19 2
16 9 20 2
16 9 21 2
16 9 22 2
16 9 23 2
16 9 24 3
16 10 19 2
16 10 20 2
16 10 21 2
16 10 22 2
16 10 23 2
16 11 21 3
17 3 20 2
17 3 22 2
17 4 19 3
17 4 20 2
17 4 21 2
17 4 22 2
17 4 23 3
17 5 19 2
17 5 20 2
17 5 21 2
17 5 22 2
17 5 23 2
17 6 17 2
17 6 18 2
17 6 19 2
17 6 20 2
17 6 22 2
17 6 23 2
17 6 24 2
17 6 25 2
17 7 17 2
17 7 18 2
17 7 19 2
17 7 20 2
17 7 23 2
17 7 25 3
17 8 17 2
17 8 18 2
17 8 19 2
17 8 20 2
17 8 22 2
17 8 23 2
17 8 24 2
17 8 25 2
17 9 19 2
17 9 20 2
17 9 21 2
17 9 22 2
17 9 23 2
17 10 19 3
17 10 20 2
17 10 21 2
17 10 22 2
17 10 23 3
17 11 20 2
17 11 22 2
18 3 20 3
18 3 21 2
18 3 22 3
18 4 20 2
18 4 21 2
18 4 22 2
18 5 18 2
18 5 19 2
18 5 20 2
18 5 21 2
18 5 22 2
18 5 23 2
18 5 24 2
18 6 17 3
18 6 18 2
18 6 19 2
18 6 20 2
18 6 23 2
18 6 24 2
18 6 25 3
18 7 18 2
18 7 19 2
18 7 20 2
18 7 23 2
18 7 24 2
18 8 17 3
18 8 18 2
18 8 19 2
18 8 20 2
18 8 23 2
18 8 24 2
18 8 25 3
18 9 18 2
18 9 19 2
18 9 20 2
18 9 21 2
18 9 22 2
18 9 23 2
18 9 24 2
18 10 20 2
18 10 21 2
18 10 22 2
18 11 20 3
18 11 21 2
18 11 22 3
19 3 21 3
19 4 19 2
19 4 20 2
19 4 21 2
19 4 22 2
19 4 23 2
19 5 18 3
19 5 19 2
19 5 20 2
19 5 21 2
19 5 22 2
19 5 23 2
19 5 24 3
19 6 18 2
19 6 19 2
19 6 23 2
19 6 24 2
19 7 17 2
19 7 18 2
19 7 19 2
19 7 23 2
19 7 24 2
19 7 25 2
19 8 18 2
19 8 19 2
19 8 23 2
19 8 24 2
19 9 18 3
19 9 19 2
19 9 20 2
19 9 21 2
19 9 22 2
19 9 23 2
19 9 24 3
19 10 19 2
19 10 20 2
19 10 21 2
19 10 22 2
19 10 23 2
19 11 21 3
20 3 20 2
20 3 22 2
20 4 19 3
20 4 20 2
20 4 21 2
20 4 22 2
20 4 23 3
20 5 19 2
20 5 20 2
20 5 21 2
20 5 22 2
20 5 23 2
20 6 17 2
20 6 18 2
20 6 19 2
20 6 20 2
20 6 21 2
20 6 22 2
20 6 23 2
20 6 24 2
20 6 25 2
20 7 17 3
20 7 18 2
20 7 19 2
20 7 23 2
20 7 24 2
20 7 25 3
20 8 17 2
20 8 18 2
20 8 19 2
20 8 20 2
20 8 21 2
20 8 22 2
20 8 23 2
20 8 24 2
20 8 25 2
20 9 19 2
20 9 20 2
20 9 21 2
20 9 22 2
20 9 23 2
20 10 19 3
20 10 20 2
20 10 21 2
20 10 22 2
20 10 23 3
20 11 20 2
20 11 22 2
21 3 20 3
21 3 21 2
21 3 22 3
21 4 20 2
21 4 21 2
21 4 22 2
21 5 5 1
21 5 18 2
21 5 19 2
21 5 20 2
21 5 21 2
21 5 22 2
21 5 23 2
21 5 24 2
21 5 37 1
21 6 4 1
21 6 5 0
21 6 17 3
21 6 18 2
21 6 19 2
21 6 20 2
21 6 21 2
21 6 22 2
21 6 23 2
21 6 24 2
21 6 25 3
21 6 37 0
21 6 38 1
21 7 3 0
21 7 4 1
21 7 5 0
21 7 6 1
21 7 18 2
21 7 19 2
21 7 23 2
21 7 24 2
21 7 36 1
21 7 37 0
21 7 38 0
21 7 39 0
21 8 4 1
21 8 5 0
21 8 17 3
21 8 18 2
21 8 19 2
21 8 20 2
21 8 21 2
21 8 22 2
21 8 23 2
21 8 24 2
21 8 25 3
21 8 37 0
21 8 38 1
21 9 5 1
21 9 18 2
21 9 19 2
21 9 20 2
21 9 21 2
21 9 22 2
21 9 23 2
21 9 24 2
21 9 37 1
21 10 20 2
21 10 21 2
21 10 22 2
21 11 20 3
21 11 21 2
21 11 22 3
22 3 21 3
22 4 4 0
22 4 5 0
22 4 19 2
22 4 20 2
22 4 21 2
22 4 22 2
22 4 23 2
22 4 37 0
22 4 38 0
22 5 3 0
22 5 4 0
22 5 5 0
22 5 6 0
22 5 18 3
22 5 19 2
22 5 20 2
22 5 21 2
22 5 22 2
22 5 23 2
22 5 24 3
22 5 36 0
22 5 37 1
22 5 38 0
22 5 39 1
22 6 2 1
22 6 3 0
22 6 4 0
22 6 5 0
22 6 6 1
22 6 7 0
22 6 18 2
22 6 19 2
22 6 20 2
22 6 21 2
22 6 22 2
22 6 23 2
22 6 24 2
22 6 35 0
22 6 36 0
22 6 37 0
22 6 38 0
22 6 39 0
22 6 40 0
22 7 2 0
22 7 3 0
22 7 4 0
22 7 5 0
22 7 6 0
22 7 7 0
22 7 8 1
22 7 17 2
22 7 18 2
22 7 19 2
22 7 23 2
22 7 24 2
22 7 25 2
22 7 34 1
22 7 35 1
22 7 36 0
22 7 37 0
22 7 38 0
22 7 39 0
22 7 40 0
22 8 2 1
22 8 3 0
22 8 4 0
22 8 5 0
22 8 6 1
22 8 7 0
22 8 18 2
22 8 19 2
22 8 20 2
22 8 21 2
22 8 22 2
22 8 23 2
22 8 24 2
22 8 35 0
22 8 36 0
22 8 37 0
22 8 38 0
22 8 39 0
22 8 40 0
22 9 3 0
22 9 4 0
22 9 5 0
22 9 6 0
22 9 18 3
22 9 19 2
22 9 20 2
22 9 21 2
22 9 22 2
22 9 23 2
22 9 24 3
22 9 36 0
22 9 37 1
22 9 38 0
22 9 39 1
22 10 4 0
22 10 5 0
22 10 19 2
22 10 20 2
22 10 21 2
22 10 22 2
22 10 23 2
22 10 37 0
22 10 38 0
22 11 21 3
23 3 20 2
23 3 22 2
23 4 3 0
23 4 6 0
23 4 7 0
23 4 19 3
23 4 20 0
23 4 21 2
23 4 22 0
23 4 23 3
23 4 35 0
23 4 36 0
23 4 39 0
23 5 2 0
23 5 3 0
23 5 6 0
23 5 7 0
23 5 19 2
23 5 20 2
23 5 21 2
23 5 22 2
23 5 23 2
23 5 35 0
23 5 36 0
23 5 39 0
23 5 40 0
23 6 2 0
23 6 3 0
23 6 4 1
23 6 5 0
23 6 6 1
23 6 7 0
23 6 8 1
23 6 17 2
23 6 18 2
23 6 19 2
23 6 20 2
23 6 21 2
23 6 23 2
23 6 24 2
23 6 25 2
23 6 34 1
23 6 35 0
23 6 36 0
23 6 37 0
23 6 38 1
23 6 39 0
23 6 40 1
23 7 2 0
23 7 3 0
23 7 4 0
23 7 5 0
23 7 6 0
23 7 7 0
23 7 8 0
23 7 9 1
23 7 17 2
23 7 18 2
23 7 19 2
23 7 23 2
23 7 24 2
23 7 25 2
23 7 33 0
23 7 34 0
23 7 35 0
23 7 36 0
23 7 37 0
23 7 38 0
23 7 39 0
23 7 40 0
23 8 2 0
23 8 3 0
23 8 4 1
23 8 5 0
23 8 6 1
23 8 7 0
23 8 8 1
23 8 17 2
23 8 18 2
23 8 19 2
23 8 20 2
23 8 21 2
23 8 23 2
23 8 24 2
23 8 25 2
23 8 34 1
23 8 35 0
23 8 36 0
23 8 37 0
23 8 38 1
23 8 39 0
23 8 40 1
23 9 2 0
23 9 3 0
23 9 6 0
23 9 7 0
23 9 19 2
23 9 20 2
23 9 21 2
23 9 22 2
23 9 23 2
23 9 35 0
23 9 36 0
23 9 39 0
23 9 40 0
23 10 3 0
23 10 6 0
23 10 7 0
23 10 19 3
23 10 20 0
23 10 21 2
23 10 22 0
23 10 23 3
23 10 35 0
23 10 36 0
23 10 39 0
23 11 20 2
23 11 22 2
24 0 21 4
24 1 19 0
24 1 20 0
24 1 21 0
24 1 22 0
24 1 23 0
24 2 17 0
24 2 18 0
24 2 19 0
24 2 20 1
24 2 21 1
24 2 22 0
24 2 23 0
24 2 24 0
24 2 25 0
24 3 15 0
24 3 16 0
24 3 17 0
24 3 18 1
24 3 19 1
24 3 20 0
24 3 21 1
24 3 22 0
24 3 23 1
24 3 24 0
24 3 25 0
24 3 26 0
24 3 27 0
24 4 2 0
24 4 8 0
24 4 9 0
24 4 13 0
24 4 14 0
24 4 15 0
24 4 16 0
24 4 17 0
24 4 18 1
24 4 19 0
24 4 20 0
24 4 21 0
24 4 22 0
24 4 23 0
24 4 24 1
24 4 25 0
24 4 26 0
24 4 27 0
24 4 28 0
24 4 29 0
24 4 33 0
24 4 34 0
24 4 40 0
24 5 2 0
24 5 8 0
24 5 9 1
24 5 12 0
24 5 13 0
24 5 14 0
24 5 15 1
24 5 16 0
24 5 17 1
24 5 18 1
24 5 20 2
24 5 21 2
24 5 24 1
24 5 25 1
24 5 26 0
24 5 27 1
24 5 28 0
24 5 29 0
24 5 30 0
24 5 33 1
24 5 34 0
24 5 40 0
24 6 2 1
24 6 3 0
24 6 7 0
24 6 8 1
24 6 9 0
24 6 10 0
24 6 12 0
24 6 13 0
24 6 14 0
24 6 15 0
24 6 16 1
24 6 17 0
24 6 18 0
24 6 19 2
24 6 23 2
24 6 24 2
24 6 25 0
24 6 26 1
24 6 27 1
24 6 28 0
24 6 29 0
24 6 30 1
24 6 32 0
24 6 33 0
24 6 34 0
24 6 35 0
24 6 39 0
24 6 40 0
24 7 1 0
24 7 2 0
24 7 3 0
24 7 4 0
24 7 6 0
24 7 7 0
24 7 8 0
24 7 9 0
24 7 10 0
24 7 11 0
24 7 12 0
24 7 13 0
24 7 14 1
24 7 15 1
24 7 16 1
24 7 17 0
24 7 18 2
24 7 23 2
24 7 24 2
24 7 25 2
24 7 26 1
24 7 27 1
24 7 28 1
24 7 29 0
24 7 30 0
24 7 31 0
24 7 32 1
24 7 33 0
24 7 34 0
24 7 35 1
24 7 36 0
24 7 38 0
24 7 39 0
24 7 40 0
24 7 41 1
24 8 2 1
24 8 3 0
24 8 7 0
24 8 8 1
24 8 9 0
24 8 10 0
24 8 12 0
24 8 13 0
24 8 14 0
24 8 15 0
24 8 16 0
24 8 17 0
24 8 18 0
24 8 19 2
24 8 23 2
24 8 24 2
24 8 25 0
24 8 26 0
24 8 27 0
24 8 28 0
24 8 29 0
24 8 30 1
24 8 32 0
24 8 33 0
24 8 34 0
24 8 35 0
24 8 39 0
24 8 40 0
24 9 2 0
24 9 8 0
24 9 9 1
24 9 12 0
24 9 13 0
24 9 14 0
24 9 15 1
24 9 16 0
24 9 17 1
24 9 18 1
24 9 20 2
24 9 21 2
24 9 24 1
24 9 25 1
24 9 26 0
24 9 27 1
24 9 28 0
24 9 29 0
24 9 30 0
24 9 33 1
24 9 34 0
24 9 40 0
24 10 2 0
24 10 8 0
24 10 9 0
24 10 13 0
24 10 14 0
24 10 15 0
24 10 16 0
24 10 17 0
24 10 18 1
24 10 19 0
24 10 20 0
24 10 21 0
24 10 22 0
24 10 23 0
24 10 24 1
24 10 25 0
24 10 26 0
24 10 27 0
24 10 28 0
24 10 29 0
24 10 33 0
24 10 34 0
24 10 40 0
24 11 15 0
24 11 16 0
24 11 17 0
24 11 18 1
24 11 19 1
24 11 20 0
24 11 21 1
24 11 22 0
24 11 23 1
24 11 24 0
24 11 25 0
24 11 26 0
24 11 27 0
24 12 17 0
24 12 18 0
24 12 19 0
24 12 20 1
24 12 21 1
24 12 22 0
24 12 23 0
24 12 24 0
24 12 25 0
24 13 19 0
24 13 20 0
24 13 21 0
24 13 22 0
24 13 23 0
24 14 21 4
25 0 20 4
25 0 21 4
25 0 22 4
25 1 18 0
25 1 19 4
25 1 20 0
25 1 21 0
25 1 22 0
25 1 23 4
25 1 24 0
25 2 16 0
25 2 17 4
25 2 18 0
25 2 19 0
25 2 20 0
25 2 21 0
25 2 22 0
25 2 23 0
25 2 24 0
25 2 25 4
25 2 26 0
25 3 14 0
25 3 15 4
25 3 16 0
25 3 17 0
25 3 18 0
25 3 19 0
25 3 20 0
25 3 21 0
25 3 22 0
25 3 23 0
25 3 24 0
25 3 25 0
25 3 26 0
25 3 27 4
25 3 28 0
25 4 10 0
25 4 11 0
25 4 12 0
25 4 13 4
25 4 14 0
25 4 15 0
25 4 16 0
25 4 17 0
25 4 18 0
25 4 19 0
25 4 20 0
25 4 21 0
25 4 22 0
25 4 23 0
25 4 24 0
25 4 25 0
25 4 26 0
25 4 27 0
25 4 28 0
25 4 29 4
25 4 30 0
25 4 31 0
25 4 32 0
25 5 2 0
25 5 10 0
25 5 11 0
25 5 12 0
25 5 13 0
25 5 14 0
25 5 15 0
25 5 16 0
25 5 17 0
25 5 18 0
25 5 19 0
25 5 23 0
25 5 24 0
25 5 25 0
25 5 26 0
25 5 27 0
25 5 28 0
25 5 29 0
25 5 30 0
25 5 31 0
25 5 32 0
25 5 40 0
25 6 1 0
25 6 2 1
25 6 9 0
25 6 10 0
25 6 11 0
25 6 12 0
25 6 13 0
25 6 14 0
25 6 15 0
25 6 16 0
25 6 17 0
25 6 18 0
25 6 24 2
25 6 25 0
25 6 26 0
25 6 27 0
25 6 28 0
25 6 29 0
25 6 30 0
25 6 31 0
25 6 32 0
25 6 33 0
25 6 40 1
25 6 41 0
25 7 0 0
25 7 1 0
25 7 2 0
25 7 3 0
25 7 8 0
25 7 9 0
25 7 10 0
25 7 11 0
25 7 12 0
25 7 13 0
25 7 14 0
25 7 15 0
25 7 16 0
25 7 17 0
25 7 24 2
25 7 25 2
25 7 26 0
25 7 27 0
25 7 28 0
25 7 29 0
25 7 30 0
25 7 31 0
25 7 32 0
25 7 33 0
25 7 34 0
25 7 39 0
25 7 40 0
25 7 41 0
25 7 42 0
25 8 1 0
25 8 2 1
25 8 9 0
25 8 10 0
25 8 11 0
25 8 12 0
25 8 13 0
25 8 14 0
25 8 15 0
25 8 16 0
25 8 17 0
25 8 18 0
25 8 24 2
25 8 25 0
25 8 26 0
25 8 27 0
25 8 28 0
25 8 29 0
25 8 30 0
25 8 31 0
25 8 32 0
25 8 33 0
25 8 40 1
25 8 41 0
25 9 2 0
25 9 10 0
25 9 11 0
25 9 12 0
25 9 13 0
25 9 14 0
25 9 15 0
25 9 16 0
25 9 17 0
25 9 18 0
25 9 19 0
25 9 23 0
25 9 24 0
25 9 25 0
25 9 26 0
25 9 27 0
25 9 28 0
25 9 29 0
25 9 30 0
25 9 31 0
25 9 32 0
25 9 40 0
25 10 10 0
25 10 11 0
25 10 12 0
25 10 13 4
25 10 14 0
25 10 15 0
25 10 16 0
25 10 17 0
25 10 18 0
25 10 19 0
25 10 20 0
25 10 21 0
25 10 22 0
25 10 23 0
25 10 24 0
25 10 25 0
25 10 26 0
25 10 27 0
25 10 28 0
25 10 29 4
25 10 30 0
25 10 31 0
25 10 32 0
25 11 14 0
25 11 15 4
25 11 16 0
25 11 17 0
25 11 18 0
25 11 19 0
25 11 20 0
25 11 21 0
25 11 22 0
25 11 23 0
25 11 24 0
25 11 25 0
25 11 26 0
25 11 27 4
25 11 28 0
25 12 16 0
25 12 17 4
25 12 18 0
25 12 19 0
25 12 20 0
25 12 21 0
25 12 22 0
25 12 23 0
25 12 24 0
25 12 25 4
25 12 26 0
25 13 18 0
25 13 19 4
25 13 20 0
25 13 21 0
25 13 22 0
25 13 23 4
25 13 24 0
25 14 20 4
25 14 21 4
25 14 22 4
26 0 21 4
26 1 19 0
26 1 20 0
26 1 21 0
26 1 22 0
26 1 23 0
26 2 17 0
26 2 18 0
26 2 19 0
26 2 20 1
26 2 21 0
26 2 22 0
26 2 23 0
26 2 24 0
26 2 25 0
26 3 15 0
26 3 16 0
26 3 17 0
26 3 18 1
26 3 19 1
26 3 20 0
26 3 21 0
26 3 22 1
26 3 23 1
26 3 24 0
26 3 25 1
26 3 26 0
26 3 27 0
26 4 13 0
26 4 14 0
26 4 15 0
26 4 16 0
26 4 17 1
26 4 18 0
26 4 23 0
26 4 24 0
26 4 25 1
26 4 26 1
26 4 27 0
26 4 28 0
26 4 29 0
26 5 1 0
26 5 11 0
26 5 12 0
26 5 13 0
26 5 14 0
26 5 15 1
26 5 16 5
26 5 17 0
26 5 18 0
26 5 25 0
26 5 26 0
26 5 27 1
26 5 28 0
26 5 29 0
26 5 30 0
26 5 31 0
26 5 41 0
26 6 1 0
26 6 2 0
26 6 10 0
26 6 11 0
26 6 12 0
26 6 13 0
26 6 14 0
26 6 15 5
26 6 16 5
26 6 27 0
26 6 28 0
26 6 29 0
26 6 30 0
26 6 31 0
26 6 32 0
26 6 40 0
26 6 41 1
26 7 0 1
26 7 1 0
26 7 2 0
26 7 9 0
26 7 10 0
26 7 11 0
26 7 12 0
26 7 13 0
26 7 14 5
26 7 15 5
26 7 16 5
26 7 27 0
26 7 28 0
26 7 29 1
26 7 30 0
26 7 31 0
26 7 32 0
26 7 33 0
26 7 40 0
26 7 41 0
26 7 42 0
26 8 1 0
26 8 2 0
26 8 10 0
26 8 11 0
26 8 12 0
26 8 13 0
26 8 14 0
26 8 15 5
26 8 16 5
26 8 27 0
26 8 28 0
26 8 29 0
26 8 30 0
26 8 31 0
26 8 32 0
26 8 40 0
26 8 41 1
26 9 1 0
26 9 11 0
26 9 12 0
26 9 13 0
26 9 14 0
26 9 15 1
26 9 16 5
26 9 17 0
26 9 18 0
26 9 25 0
26 9 26 0
26 9 27 1
26 9 28 0
26 9 29 0
26 9 30 0
26 9 31 0
26 9 41 0
26 10 13 0
26 10 14 0
26 10 15 0
26 10 16 0
26 10 17 1
26 10 18 0
26 10 23 0
26 10 24 0
26 10 25 1
26 10 26 1
26 10 27 0
26 10 28 0
26 10 29 0
26 11 15 0
26 11 16 0
26 11 17 0
26 11 18 1
26 11 19 1
26 11 20 0
26 11 21 0
26 11 22 1
26 11 23 1
26 11 24 0
26 11 25 1
26 11 26 0
26 11 27 0
26 12 17 0
26 12 18 0
26 12 19 0
26 12 20 1
26 12 21 0
26 12 22 0
26 12 23 0
26 12 24 0
26 12 25 0
26 13 19 0
26 13 20 0
26 13 21 0
26 13 22 0
26 13 23 0
26 14 21 4
27 3 21 6
27 4 18 7
27 4 19 7
27 4 20 5
27 4 21 5
27 4 22 7
27 4 23 7
27 4 24 7
27 5 1 0
27 5 16 5
27 5 17 7
27 5 18 5
27 5 19 5
27 5 20 5
27 5 21 5
27 5 22 5
27 5 23 5
27 5 24 7
27 5 25 5
27 5 26 7
27 5 41 0
27 6 1 0
27 6 12 0
27 6 15 7
27 6 16 5
27 6 17 5
27 6 18 5
27 6 24 5
27 6 25 5
27 6 26 5
27 6 27 7
27 6 30 0
27 6 41 0
27 7 1 0
27 7 2 0
27 7 5 0
27 7 10 0
27 7 11 0
27 7 12 0
27 7 14 7
27 7 15 5
27 7 16 5
27 7 17 5
27 7 26 5
27 7 27 5
27 7 28 7
27 7 30 0
27 7 31 0
27 7 32 0
27 7 37 0
27 7 40 0
27 7 41 0
27 8 1 0
27 8 12 0
27 8 15 7
27 8 16 5
27 8 17 5
27 8 18 5
27 8 24 5
27 8 25 5
27 8 26 5
27 8 27 7
27 8 30 0
27 8 41 0
27 9 1 0
27 9 16 5
27 9 17 7
27 9 18 5
27 9 19 5
27 9 20 5
27 9 21 5
27 9 22 5
27 9 23 5
27 9 24 7
27 9 25 5
27 9 26 7
27 9 41 0
27 10 18 7
27 10 19 7
27 10 20 5
27 10 21 5
27 10 22 7
27 10 23 7
27 10 24 7
27 11 21 6
28 3 21 6
28 4 18 7
28 4 19 5
28 4 20 5
28 4 21 5
28 4 22 7
28 4 23 5
28 4 24 7
28 5 2 0
28 5 16 5
28 5 17 5
28 5 18 5
28 5 19 5
28 5 20 5
28 5 21 5
28 5 22 5
28 5 23 5
28 5 24 5
28 5 25 5
28 5 26 5
28 5 40 0
28 6 2 1
28 6 3 0
28 6 5 0
28 6 15 5
28 6 16 5
28 6 17 5
28 6 18 5
28 6 19 5
28 6 20 5
28 6 21 5
28 6 22 5
28 6 23 5
28 6 24 5
28 6 25 5
28 6 26 5
28 6 27 5
28 6 37 0
28 6 39 0
28 6 40 0
28 7 1 0
28 7 2 0
28 7 3 0
28 7 4 0
28 7 5 0
28 7 14 7
28 7 15 5
28 7 16 5
28 7 17 5
28 7 18 5
28 7 24 5
28 7 25 5
28 7 26 5
28 7 27 5
28 7 28 7
28 7 37 0
28 7 38 0
28 7 39 0
28 7 40 0
28 7 41 0
28 8 2 1
28 8 3 0
28 8 5 0
28 8 15 5
28 8 16 5
28 8 17 5
28 8 18 5
28 8 19 5
28 8 20 5
28 8 21 5
28 8 22 5
28 8 23 5
28 8 24 5
28 8 25 5
28 8 26 5
28 8 27 5
28 8 37 0
28 8 39 0
28 8 40 0
28 9 2 0
28 9 16 5
28 9 17 5
28 9 18 5
28 9 19 5
28 9 20 5
28 9 21 5
28 9 22 5
28 9 23 5
28 9 24 5
28 9 25 5
28 9 26 5
28 9 40 0
28 10 18 7
28 10 19 5
28 10 20 5
28 10 21 5
28 10 22 7
28 10 23 5
28 10 24 7
28 11 21 6
29 3 21 6
29 4 18 5
29 4 19 5
29 4 20 5
29 4 21 5
29 4 22 7
29 4 23 5
29 4 24 5
29 5 3 0
29 5 16 7
29 5 17 5
29 5 18 5
29 5 19 5
29 5 20 5
29 5 21 5
29 5 22 5
29 5 23 5
29 5 24 5
29 5 25 7
29 5 26 5
29 5 39 0
29 6 3 0
29 6 4 0
29 6 15 5
29 6 16 5
29 6 17 5
29 6 18 5
29 6 19 5
29 6 20 5
29 6 21 5
29 6 22 5
29 6 23 5
29 6 24 5
29 6 25 5
29 6 26 5
29 6 27 5
29 6 38 0
29 6 39 0
29 7 3 0
29 7 4 0
29 7 5 0
29 7 14 5
29 7 15 5
29 7 16 5
29 7 17 5
29 7 18 5
29 7 24 5
29 7 25 5
29 7 26 5
29 7 27 5
29 7 28 5
29 7 37 0
29 7 38 0
29 7 39 0
29 8 3 0
29 8 4 0
29 8 15 5
29 8 16 5
29 8 17 5
29 8 18 5
29 8 19 5
29 8 20 5
29 8 21 5
29 8 22 5
29 8 23 5
29 8 24 5
29 8 25 5
29 8 26 5
29 8 27 5
29 8 38 0
29 8 39 0
29 9 3 0
29 9 16 7
29 9 17 5
29 9 18 5
29 9 19 5
29 9 20 5
29 9 21 5
29 9 22 5
29 9 23 5
29 9 24 5
29 9 25 7
29 9 26 5
29 9 39 0
29 10 18 5
29 10 19 5
29 10 20 5
29 10 21 5
29 10 22 7
29 10 23 5
29 10 24 5
29 11 21 6
30 3 21 6
30 4 18 5
30 4 19 5
30 4 20 5
30 4 21 5
30 4 22 5
30 4 23 5
30 4 24 5
30 5 16 5
30 5 17 5
30 5 18 5
30 5 19 5
30 5 20 5
30 5 21 5
30 5 22 5
30 5 23 5
30 5 24 5
30 5 25 5
30 5 26 5
30 6 15 5
30 6 16 5
30 6 17 5
30 6 18 5
30 6 19 5
30 6 20 5
30 6 21 5
30 6 22 5
30 6 23 5
30 6 24 5
30 6 25 5
30 6 26 5
30 6 27 5
30 7 14 5
30 7 15 5
30 7 16 5
30 7 17 5
30 7 18 5
30 7 24 5
30 7 25 5
30 7 26 5
30 7 27 5
30 7 28 5
30 8 15 5
30 8 16 5
30 8 17 5
30 8 18 5
30 8 19 5
30 8 20 5
30 8 21 5
30 8 22 5
30 8 23 5
30 8 24 5
30 8 25 5
30 8 26 5
30 8 27 5
30 9 16 5
30 9 17 5
30 9 18 5
30 9 19 5
30 9 20 5
30 9 21 5
30 9 22 5
30 9 23 5
30 9 24 5
30 9 25 5
30 9 26 5
30 10 18 5
30 10 19 5
30 10 20 5
30 10 21 5
30 10 22 5
30 10 23 5
30 10 24 5
30 11 21 6
31 3 21 6
31 4 18 5
31 4 19 5
31 4 20 5
31 4 21 5
31 4 22 5
31 4 23 5
31 4 24 5
31 5 16 5
31 5 17 5
31 5 18 5
31 5 19 5
31 5 20 5
31 5 21 5
31 5 22 5
31 5 23 5
31 5 24 5
31 5 25 5
31 5 26 5
31 6 15 5
31 6 16 5
31 6 17 5
31 6 18 5
31 6 19 5
31 6 22 5
31 6 23 5
31 6 24 5
31 6 25 5
31 6 26 5
31 6 27 5
31 7 15 5
31 7 16 5
31 7 17 5
31 7 18 5
31 7 24 5
31 7 25 5
31 7 26 5
31 7 27 5
31 8 15 5
31 8 16 5
31 8 17 5
31 8 18 5
31 8 19 5
31 8 22 5
31 8 23 5
31 8 24 5
31 8 25 5
31 8 26 5
31 8 27 5
31 9 16 5
31 9 17 5
31 9 18 5
31 9 19 5
31 9 20 5
31 9 21 5
31 9 22 5
31 9 23 5
31 9 24 5
31 9 25 5
31 9 26 5
31 10 18 5
31 10 19 5
31 10 20 5
31 10 21 5
31 10 22 5
31 10 23 5
31 10 24 5
31 11 21 6
32 3 21 6
32 4 18 5
32 4 19 5
32 4 20 5
32 4 21 5
32 4 22 5
32 4 23 5
32 4 24 5
32 5 16 5
32 5 17 5
32 5 18 5
32 5 19 5
32 5 20 5
32 5 21 5
32 5 22 5
32 5 23 5
32 5 24 5
32 5 25 5
32 5 26 5
32 6 15 5
32 6 16 5
32 6 17 5
32 6 18 5
32 6 22 5
32 6 23 5
32 6 24 5
32 6 25 5
32 6 26 5
32 6 27 5
32 7 15 5
32 7 16 5
32 7 17 5
32 7 25 5
32 7 26 5
32 7 27 5
32 8 15 5
32 8 16 5
32 8 17 5
32 8 18 5
32 8 22 5
32 8 23 5
32 8 24 5
32 8 25 5
32 8 26 5
32 8 27 5
32 9 16 5
32 9 17 5
32 9 18 5
32 9 19 5
32 9 20 5
32 9 21 5
32 9 22 5
32 9 23 5
32 9 24 5
32 9 25 5
32 9 26 5
32 10 18 5
32 10 19 5
32 10 20 5
32 10 21 5
32 10 22 5
32 10 23 5
32 10 24 5
32 11 21 6
33 3 21 6
33 4 18 5
33 4 19 5
33 4 20 5
33 4 21 5
33 4 22 5
33 4 23 5
33 4 24 5
33 5 16 5
33 5 17 5
33 5 18 5
33 5 19 5
33 5 20 5
33 5 21 5
33 5 22 5
33 5 23 5
33 5 24 5
33 5 25 5
33 5 26 5
33 6 15 5
33 6 16 5
33 6 17 5
33 6 18 5
33 6 19 5
33 6 20 5
33 6 21 5
33 6 22 5
33 6 23 5
33 6 24 5
33 6 25 5
33 6 26 5
33 6 27 5
33 7 15 5
33 7 16 5
33 7 17 5
33 7 24 5
33 7 25 5
33 7 26 5
33 7 27 5
33 8 15 5
33 8 16 5
33 8 17 5
33 8 18 5
33 8 19 5
33 8 20 5
33 8 21 5
33 8 22 5
33 8 23 5
33 8 24 5
33 8 25 5
33 8 26 5
33 8 27 5
33 9 16 5
33 9 17 5
33 9 18 5
33 9 19 5
33 9 20 5
33 9 21 5
33 9 22 5
33 9 23 5
33 9 24 5
33 9 25 5
33 9 26 5
33 10 18 5
33 10 19 5
33 10 20 5
33 10 21 5
33 10 22 5
33 10 23 5
33 10 24 5
33 11 21 6
34 3 21 6
34 4 18 5
34 4 19 5
34 4 20 5
34 4 21 5
34 4 22 5
34 4 23 5
34 4 24 5
34 5 16 5
34 5 17 5
34 5 18 5
34 5 19 5
34 5 20 5
34 5 21 5
34 5 22 5
34 5 23 5
34 5 24 5
34 5 25 5
34 5 26 5
34 6 15 5
34 6 16 5
34 6 17 5
34 6 18 5
34 6 19 5
34 6 20 5
34 6 21 5
34 6 22 5
34 6 23 5
34 6 24 5
34 6 25 5
34 6 26 5
34 6 27 5
34 7 15 5
34 7 16 5
34 7 17 5
34 7 18 5
34 7 24 5
34 7 25 5
34 7 26 5
34 7 27 5
34 8 15 5
34 8 16 5
34 8 17 5
34 8 18 5
34 8 19 5
34 8 20 5
34 8 21 5
34 8 22 5
34 8 23 5
34 8 24 5
34 8 25 5
34 8 26 5
34 8 27 5
34 9 16 5
34 9 17 5
34 9 18 5
34 9 19 5
34 9 20 5
34 9 21 5
34 9 22 5
34 9 23 5
34 9 24 5
34 9 25 5
34 9 26 5
34 10 18 5
34 10 19 5
34 10 20 5
34 10 21 5
34 10 22 5
34 10 23 5
34 10 24 5
34 11 21 6
35 3 21 6
35 4 18 5
35 4 19 5
35 4 20 5
35 4 21 5
35 4 22 5
35 4 23 5
35 4 24 5
35 5 17 5
35 5 18 5
35 5 19 5
35 5 20 5
35 5 21 5
35 5 22 5
35 5 23 5
35 5 24 5
35 5 25 5
35 6 15 5
35 6 16 5
35 6 17 5
35 6 18 5
35 6 19 5
35 6 20 5
35 6 21 5
35 6 23 5
35 6 24 5
35 6 25 5
35 6 26 5
35 6 27 5
35 7 15 5
35 7 16 5
35 7 17 5
35 7 18 5
35 7 24 5
35 7 25 5
35 7 26 5
35 7 27 5
35 8 15 5
35 8 16 5
35 8 17 5
35 8 18 5
35 8 19 5
35 8 20 5
35 8 21 5
35 8 23 5
35 8 24 5
35 8 25 5
35 8 26 5
35 8 27 5
35 9 17 5
35 9 18 5
35 9 19 5
35 9 20 5
35 9 21 5
35 9 22 5
35 9 23 5
35 9 24 5
35 9 25 5
35 10 18 5
35 10 19 5
35 10 20 5
35 10 21 5
35 10 22 5
35 10 23 5
35 10 24 5
35 11 21 6
36 3 21 6
36 4 18 5
36 4 19 5
36 4 20 5
36 4 21 5
36 4 22 5
36 4 23 5
36 4 24 5
36 5 17 5
36 5 18 5
36 5 19 5
36 5 20 5
36 5 21 5
36 5 22 5
36 5 23 5
36 5 24 5
36 5 25 5
36 6 16 5
36 6 17 5
36 6 18 5
36 6 19 5
36 6 20 5
36 6 21 5
36 6 23 5
36 6 24 5
36 6 25 5
36 6 26 5
36 7 15 5
36 7 16 5
36 7 17 5
36 7 18 5
36 7 24 5
36 7 25 5
36 7 26 5
36 7 27 5
36 8 16 5
36 8 17 5
36 8 18 5
36 8 19 5
36 8 20 5
36 8 21 5
36 8 23 5
36 8 24 5
36 8 25 5
36 8 26 5
36 9 17 5
36 9 18 5
36 9 19 5
36 9 20 5
36 9 21 5
36 9 22 5
36 9 23 5
36 9 24 5
36 9 25 5
36 10 18 5
36 10 19 5
36 10 20 5
36 10 21 5
36 10 22 5
36 10 23 5
36 10 24 5
36 11 21 6
37 3 21 6
37 4 18 5
37 4 19 5
37 4 20 5
37 4 21 5
37 4 22 5
37 4 23 5
37 4 24 5
37 5 17 5
37 5 18 5
37 5 19 5
37 5 20 5
37 5 21 5
37 5 22 5
37 5 23 5
37 5 24 5
37 5 25 5
37 6 16 5
37 6 17 5
37 6 18 5
37 6 19 5
37 6 20 5
37 6 21 5
37 6 23 5
37 6 24 5
37 6 25 5
37 6 26 5
37 7 15 5
37 7 16 5
37 7 17 5
37 7 18 5
37 7 19 5
37 7 24 5
37 7 25 5
37 7 26 5
37 7 27 5
37 8 16 5
37 8 17 5
37 8 18 5
37 8 19 5
37 8 20 5
37 8 21 5
37 8 23 5
37 8 24 5
37 8 25 5
37 8 26 5
37 9 17 5
37 9 18 5
37 9 19 5
37 9 20 5
37 9 21 5
37 9 22 5
37 9 23 5
37 9 24 5
37 9 25 5
37 10 18 5
37 10 19 5
37 10 20 5
37 10 21 5
37 10 22 5
37 10 23 5
37 10 24 5
37 11 21 6
38 3 21 6
38 4 19 5
38 4 20 5
38 4 21 5
38 4 22 5
38 4 23 5
38 5 17 5
38 5 18 5
38 5 19 5
38 5 20 5
38 5 21 5
38 5 22 5
38 5 23 5
38 5 24 5
38 5 25 5
38 6 16 5
38 6 17 5
38 6 18 5
38 6 19 5
38 6 20 5
38 6 21 5
38 6 23 5
38 6 24 5
38 6 25 5
38 6 26 5
38 7 15 5
38 7 16 5
38 7 17 5
38 7 18 5
38 7 19 5
38 7 24 5
38 7 25 5
38 7 26 5
38 7 27 5
38 8 16 5
38 8 17 5
38 8 18 5
38 8 19 5
38 8 20 5
38 8 21 5
38 8 23 5
38 8 24 5
38 8 25 5
38 8 26 5
38 9 17 5
38 9 18 5
38 9 19 5
38 9 20 5
38 9 21 5
38 9 22 5
38 9 23 5
38 9 24 5
38 9 25 5
38 10 19 5
38 10 20 5
38 10 21 5
38 10 22 5
38 10 23 5
38 11 21 6
39 3 21 6
39 4 19 5
39 4 20 5
39 4 21 5
39 4 22 5
39 4 23 5
39 5 17 5
39 5 18 5
39 5 19 5
39 5 20 5
39 5 21 5
39 5 22 5
39 5 23 5
39 5 24 5
39 5 25 5
39 6 16 5
39 6 17 5
39 6 18 5
39 6 19 5
39 6 20 5
39 6 21 5
39 6 23 5
39 6 24 5
39 6 25 5
39 6 26 5
39 7 15 5
39 7 16 5
39 7 17 5
39 7 18 5
39 7 19 5
39 7 24 5
39 7 25 5
39 7 26 5
39 7 27 5
39 8 16 5
39 8 17 5
39 8 18 5
39 8 19 5
39 8 20 5
39 8 21 5
39 8 23 5
39 8 24 5
39 8 25 5
39 8 26 5
39 9 17 5
39 9 18 5
39 9 19 5
39 9 20 5
39 9 21 5
39 9 22 5
39 9 23 5
39 9 24 5
39 9 25 5
39 10 19 5
39 10 20 5
39 10 21 5
39 10 22 5
39 10 23 5
39 11 21 6
40 3 21 6
40 4 19 5
40 4 20 5
40 4 21 5
40 4 22 5
40 4 23 5
40 5 17 5
40 5 18 5
40 5 19 5
40 5 20 5
40 5 21 5
40 5 22 5
40 5 23 5
40 5 24 5
40 5 25 5
40 6 16 5
40 6 17 5
40 6 18 5
40 6 19 5
40 6 20 5
40 6 21 5
40 6 22 5
40 6 23 5
40 6 24 5
40 6 25 5
40 6 26 5
40 7 15 5
40 7 16 5
40 7 17 5
40 7 18 5
40 7 24 5
40 7 25 5
40 7 26 5
40 7 27 5
40 8 16 5
40 8 17 5
40 8 18 5
40 8 19 5
40 8 20 5
40 8 21 5
40 8 22 5
40 8 23 5
40 8 24 5
40 8 25 5
40 8 26 5
40 9 17 5
40 9 18 5
40 9 19 5
40 9 20 5
40 9 21 5
40 9 22 5
40 9 23 5
40 9 24 5
40 9 25 5
40 10 19 5
40 10 20 5
40 10 21 5
40 10 22 5
40 10 23 5
40 11 21 6
41 3 21 6
41 4 19 5
41 4 20 5
41 4 21 5
41 4 22 5
41 4 23 5
41 5 17 5
41 5 18 5
41 5 19 5
41 5 20 5
41 5 21 5
41 5 22 5
41 5 23 5
41 5 24 5
41 5 25 5
41 6 16 5
41 6 17 5
41 6 18 5
41 6 19 5
41 6 20 5
41 6 21 5
41 6 22 5
41 6 23 5
41 6 24 5
41 6 25 5
41 6 26 5
41 7 15 5
41 7 16 5
41 7 17 5
41 7 18 5
41 7 24 5
41 7 25 5
41 7 26 5
41 7 27 5
41 8 16 5
41 8 17 5
41 8 18 5
41 8 19 5
41 8 20 5
41 8 21 5
41 8 22 5
41 8 23 5
41 8 24 5
41 8 25 5
41 8 26 5
41 9 17 5
41 9 18 5
41 9 19 5
41 9 20 5
41 9 21 5
41 9 22 5
41 9 23 5
41 9 24 5
41 9 25 5
41 10 19 5
41 10 20 5
41 10 21 5
41 10 22 5
41 10 23 5
41 11 21 6
42 3 21 6
42 4 19 5
42 4 20 5
42 4 21 5
42 4 22 5
42 4 23 5
42 5 17 5
42 5 18 5
42 5 19 5
42 5 20 5
42 5 21 5
42 5 22 5
42 5 23 5
42 5 24 5
42 5 25 5
42 6 16 5
42 6 17 5
42 6 18 5
42 6 19 5
42 6 20 5
42 6 21 5
42 6 22 5
42 6 23 5
42 6 24 5
42 6 25 5
42 6 26 5
42 7 15 5
42 7 16 5
42 7 17 5
42 7 18 5
42 7 19 5
42 7 24 5
42 7 25 5
42 7 26 5
42 7 27 5
42 8 16 5
42 8 17 5
42 8 18 5
42 8 19 5
42 8 20 5
42 8 21 5
42 8 22 5
42 8 23 5
42 8 24 5
42 8 25 5
42 8 26 5
42 9 17 5
42 9 18 5
42 9 19 5
42 9 20 5
42 9 21 5
42 9 22 5
42 9 23 5
42 9 24 5
42 9 25 5
42 10 19 5
42 10 20 5
42 10 21 5
42 10 22 5
42 10 23 5
42 11 21 6
43 3 21 6
43 4 19 5
43 4 20 5
43 4 21 5
43 4 22 5
43 4 23 5
43 5 18 5
43 5 19 5
43 5 20 5
43 5 21 5
43 5 22 5
43 5 23 5
43 5 24 5
43 6 16 5
43 6 17 5
43 6 18 5
43 6 19 5
43 6 20 5
43 6 21 5
43 6 22 5
43 6 23 5
43 6 24 5
43 6 25 5
43 6 26 5
43 7 15 5
43 7 16 5
43 7 17 5
43 7 18 5
43 7 19 5
43 7 24 5
43 7 25 5
43 7 26 5
43 7 27 5
43 8 16 5
43 8 17 5
43 8 18 5
43 8 19 5
43 8 20 5
43 8 21 5
43 8 22 5
43 8 23 5
43 8 24 5
43 8 25 5
43 8 26 5
43 9 18 5
43 9 19 5
43 9 20 5
43 9 21 5
43 9 22 5
43 9 23 5
43 9 24 5
43 10 19 5
43 10 20 5
43 10 21 5
43 10 22 5
43 10 23 5
43 11 21 6
44 3 21 6
44 4 19 5
44 4 20 5
44 4 21 5
44 4 22 5
44 4 23 5
44 5 18 5
44 5 19 5
44 5 20 5
44 5 21 5
44 5 22 5
44 5 23 5
44 5 24 5
44 6 17 5
44 6 18 5
44 6 19 5
44 6 20 5
44 6 21 5
44 6 22 5
44 6 23 5
44 6 24 5
44 6 25 5
44 7 15 5
44 7 16 5
44 7 17 5
44 7 18 5
44 7 19 5
44 7 24 5
44 7 25 5
44 7 26 5
44 7 27 5
44 8 17 5
44 8 18 5
44 8 19 5
44 8 20 5
44 8 21 5
44 8 22 5
44 8 23 5
44 8 24 5
44 8 25 5
44 9 18 5
44 9 19 5
44 9 20 5
44 9 21 5
44 9 22 5
44 9 23 5
44 9 24 5
44 10 19 5
44 10 20 5
44 10 21 5
44 10 22 5
44 10 23 5
44 11 21 6
45 3 21 6
45 4 19 5
45 4 20 5
45 4 21 5
45 4 22 5
45 4 23 5
45 5 18 5
45 5 19 5
45 5 20 5
45 5 21 5
45 5 22 5
45 5 23 5
45 5 24 5
45 6 17 5
45 6 18 5
45 6 19 5
45 6 20 5
45 6 24 5
45 6 25 5
45 7 16 5
45 7 17 5
45 7 18 5
45 7 19 5
45 7 24 5
45 7 25 5
45 7 26 5
45 8 17 5
45 8 18 5
45 8 19 5
45 8 20 5
45 8 24 5
45 8 25 5
45 9 18 5
45 9 19 5
45 9 20 5
45 9 21 5
45 9 22 5
45 9 23 5
45 9 24 5
45 10 19 5
45 10 20 5
45 10 21 5
45 10 22 5
45 10 23 5
45 11 21 6
46 3 21 6
46 4 19 5
46 4 20 5
46 4 21 5
46 4 22 5
46 4 23 5
46 5 18 5
46 5 19 5
46 5 20 5
46 5 21 5
46 5 22 5
46 5 23 5
46 5 24 5
46 6 17 5
46 6 18 5
46 6 19 5
46 6 20 5
46 6 23 5
46 6 24 5
46 6 25 5
46 7 16 5
46 7 17 5
46 7 18 5
46 7 19 5
46 7 23 5
46 7 24 5
46 7 25 5
46 7 26 5
46 8 17 5
46 8 18 5
46 8 19 5
46 8 20 5
46 8 23 5
46 8 24 5
46 8 25 5
46 9 18 5
46 9 19 5
46 9 20 5
46 9 21 5
46 9 22 5
46 9 23 5
46 9 24 5
46 10 19 5
46 10 20 5
46 10 21 5
46 10 22 5
46 10 23 5
46 11 21 6
47 3 21 6
47 4 19 5
47 4 20 5
47 4 21 5
47 4 22 5
47 4 23 5
47 5 18 5
47 5 19 5
47 5 20 5
47 5 21 5
47 5 22 5
47 5 23 5
47 5 24 5
47 6 17 5
47 6 18 5
47 6 19 5
47 6 20 5
47 6 23 5
47 6 24 5
47 6 25 5
47 7 16 5
47 7 17 5
47 7 18 5
47 7 19 5
47 7 23 5
47 7 24 5
47 7 25 5
47 7 26 5
47 8 17 5
47 8 18 5
47 8 19 5
47 8 20 5
47 8 23 5
47 8 24 5
47 8 25 5
47 9 18 5
47 9 19 5
47 9 20 5
47 9 21 5
47 9 22 5
47 9 23 5
47 9 24 5
47 10 19 5
47 10 20 5
47 10 21 5
47 10 22 5
47 10 23 5
47 11 21 6
48 3 21 6
48 4 19 5
48 4 20 5
48 4 21 5
48 4 22 5
48 4 23 5
48 5 18 5
48 5 19 5
48 5 20 5
48 5 21 5
48 5 22 5
48 5 23 5
48 5 24 5
48 6 17 5
48 6 18 5
48 6 19 5
48 6 20 5
48 6 23 5
48 6 24 5
48 6 25 5
48 7 16 5
48 7 17 5
48 7 18 5
48 7 19 5
48 7 23 5
48 7 24 5
48 7 25 5
48 7 26 5
48 8 17 5
48 8 18 5
48 8 19 5
48 8 20 5
48 8 23 5
48 8 24 5
48 8 25 5
48 9 18 5
48 9 19 5
48 9 20 5
48 9 21 5
48 9 22 5
48 9 23 5
48 9 24 5
48 10 19 5
48 10 20 5
48 10 21 5
48 10 22 5
48 10 23 5
48 11 21 6
49 3 21 6
49 4 19 5
49 4 20 5
49 4 21 5
49 4 22 5
49 4 23 5
49 5 18 5
49 5 19 5
49 5 20 5
49 5 21 5
49 5 22 5
49 5 23 5
49 5 24 5
49 6 17 5
49 6 18 5
49 6 19 5
49 6 20 5
49 6 21 5
49 6 23 5
49 6 24 5
49 6 25 5
49 7 16 5
49 7 17 5
49 7 18 5
49 7 19 5
49 7 20 5
49 7 23 5
49 7 24 5
49 7 25 5
49 7 26 5
49 8 17 5
49 8 18 5
49 8 19 5
49 8 20 5
49 8 21 5
49 8 23 5
49 8 24 5
49 8 25 5
49 9 18 5
49 9 19 5
49 9 20 5
49 9 21 5
49 9 22 5
49 9 23 5
49 9 24 5
49 10 19 5
49 10 20 5
49 10 21 5
49 10 22 5
49 10 23 5
49 11 21 6
50 3 21 6
50 4 19 5
50 4 20 5
50 4 21 5
50 4 22 5
50 4 23 5
50 5 18 5
50 5 19 5
50 5 20 5
50 5 21 5
50 5 22 5
50 5 23 5
50 5 24 5
50 6 17 5
50 6 18 5
50 6 19 5
50 6 20 5
50 6 21 5
50 6 23 5
50 6 24 5
50 6 25 5
50 7 16 5
50 7 17 5
50 7 18 5
50 7 19 5
50 7 20 5
50 7 23 5
50 7 24 5
50 7 25 5
50 7 26 5
50 8 17 5
50 8 18 5
50 8 19 5
50 8 20 5
50 8 21 5
50 8 23 5
50 8 24 5
50 8 25 5
50 9 18 5
50 9 19 5
50 9 20 5
50 9 21 5
50 9 22 5
50 9 23 5
50 9 24 5
50 10 19 5
50 10 20 5
50 10 21 5
50 10 22 5
50 10 23 5
50 11 21 6
51 3 21 6
51 4 20 5
51 4 21 5
51 4 22 5
51 5 18 5
51 5 19 5
51 5 20 5
51 5 21 5
51 5 22 5
51 5 23 5
51 5 24 5
51 6 17 5
51 6 18 5
51 6 19 5
51 6 20 5
51 6 21 5
51 6 23 5
51 6 24 5
51 6 25 5
51 7 16 5
51 7 17 5
51 7 18 5
51 7 19 5
51 7 20 5
51 7 23 5
51 7 24 5
51 7 25 5
51 7 26 5
51 8 17 5
51 8 18 5
51 8 19 5
51 8 20 5
51 8 21 5
51 8 23 5
51 8 24 5
51 8 25 5
51 9 18 5
51 9 19 5
51 9 20 5
51 9 21 5
51 9 22 5
51 9 23 5
51 9 24 5
51 10 20 5
51 10 21 5
51 10 22 5
51 11 21 6
52 3 21 6
52 4 20 5
52 4 21 5
52 4 22 5
52 5 18 5
52 5 19 5
52 5 20 5
52 5 21 5
52 5 22 5
52 5 23 5
52 5 24 5
52 6 17 5
52 6 18 5
52 6 19 5
52 6 20 5
52 6 21 5
52 6 23 5
52 6 24 5
52 6 25 5
52 7 16 5
52 7 17 5
52 7 18 5
52 7 19 5
52 7 20 5
52 7 23 5
52 7 24 5
52 7 25 5
52 7 26 5
52 8 17 5
52 8 18 5
52 8 19 5
52 8 20 5
52 8 21 5
52 8 23 5
52 8 24 5
52 8 25 5
52 9 18 5
52 9 19 5
52 9 20 5
52 9 21 5
52 9 22 5
52 9 23 5
52 9 24 5
52 10 20 5
52 10 21 5
52 10 22 5
52 11 21 6
53 3 21 6
53 4 20 5
53 4 21 5
53 4 22 5
53 5 18 5
53 5 19 5
53 5 20 5
53 5 21 5
53 5 22 5
53 5 23 5
53 5 24 5
53 6 17 5
53 6 18 5
53 6 19 5
53 6 20 5
53 6 21 5
53 6 23 5
53 6 24 5
53 6 25 5
53 7 16 5
53 7 17 5
53 7 18 5
53 7 19 5
53 7 20 5
53 7 23 5
53 7 24 5
53 7 25 5
53 7 26 5
53 8 17 5
53 8 18 5
53 8 19 5
53 8 20 5
53 8 21 5
53 8 23 5
53 8 24 5
53 8 25 5
53 9 18 5
53 9 19 5
53 9 20 5
53 9 21 5
53 9 22 5
53 9 23 5
53 9 24 5
53 10 20 5
53 10 21 5
53 10 22 5
53 11 21 6
54 3 21 6
54 4 20 5
54 4 21 5
54 4 22 5
54 5 18 5
54 5 19 5
54 5 20 5
54 5 21 5
54 5 22 5
54 5 23 5
54 5 24 5
54 6 17 5
54 6 18 5
54 6 19 5
54 6 20 5
54 6 23 5
54 6 24 5
54 6 25 5
54 7 16 5
54 7 17 5
54 7 18 5
54 7 19 5
54 7 20 5
54 7 23 5
54 7 24 5
54 7 25 5
54 7 26 5
54 8 17 5
54 8 18 5
54 8 19 5
54 8 20 5
54 8 23 5
54 8 24 5
54 8 25 5
54 9 18 5
54 9 19 5
54 9 20 5
54 9 21 5
54 9 22 5
54 9 23 5
54 9 24 5
54 10 20 5
54 10 21 5
54 10 22 5
54 11 21 6
55 3 21 6
55 4 20 5
55 4 21 5
55 4 22 5
55 5 19 5
55 5 20 5
55 5 21 5
55 5 22 5
55 5 23 5
55 6 17 5
55 6 18 5
55 6 19 5
55 6 20 5
55 6 23 5
55 6 24 5
55 6 25 5
55 7 16 5
55 7 17 5
55 7 18 5
55 7 19 5
55 7 20 5
55 7 23 5
55 7 24 5
55 7 25 5
55 7 26 5
55 8 17 5
55 8 18 5
55 8 19 5
55 8 20 5
55 8 23 5
55 8 24 5
55 8 25 5
55 9 19 5
55 9 20 5
55 9 21 5
55 9 22 5
55 9 23 5
55 10 20 5
55 10 21 5
55 10 22 5
55 11 21 6
56 3 21 6
56 4 20 5
56 4 21 5
56 4 22 5
56 5 19 5
56 5 20 5
56 5 21 5
56 5 22 5
56 5 23 5
56 6 18 5
56 6 19 5
56 6 20 5
56 6 22 5
56 6 23 5
56 6 24 5
56 7 16 5
56 7 17 5
56 7 18 5
56 7 19 5
56 7 20 5
56 7 22 5
56 7 23 5
56 7 24 5
56 7 25 5
56 7 26 5
56 8 18 5
56 8 19 5
56 8 20 5
56 8 22 5
56 8 23 5
56 8 24 5
56 9 19 5
56 9 20 5
56 9 21 5
56 9 22 5
56 9 23 5
56 10 20 5
56 10 21 5
56 10 22 5
56 11 21 6
57 3 21 6
57 4 20 5
57 4 21 5
57 4 22 5
57 5 19 5
57 5 20 5
57 5 21 5
57 5 22 5
57 5 23 5
57 6 18 5
57 6 19 5
57 6 20 5
57 6 22 5
57 6 23 5
57 6 24 5
57 7 17 5
57 7 18 5
57 7 19 5
57 7 20 5
57 7 22 5
57 7 23 5
57 7 24 5
57 7 25 5
57 8 18 5
57 8 19 5
57 8 20 5
57 8 22 5
57 8 23 5
57 8 24 5
57 9 19 5
57 9 20 5
57 9 21 5
57 9 22 5
57 9 23 5
57 10 20 5
57 10 21 5
57 10 22 5
57 11 21 6
58 3 21 6
58 4 20 5
58 4 21 5
58 4 22 5
58 5 19 5
58 5 20 5
58 5 21 5
58 5 22 5
58 5 23 5
58 6 18 5
58 6 19 5
58 6 20 5
58 6 21 5
58 6 22 5
58 6 23 5
58 6 24 5
58 7 17 5
58 7 18 5
58 7 19 5
58 7 20 5
58 7 22 5
58 7 23 5
58 7 24 5
58 7 25 5
58 8 18 5
58 8 19 5
58 8 20 5
58 8 21 5
58 8 22 5
58 8 23 5
58 8 24 5
58 9 19 5
58 9 20 5
58 9 21 5
58 9 22 5
58 9 23 5
58 10 20 5
58 10 21 5
58 10 22 5
58 11 21 6
59 3 21 6
59 4 20 5
59 4 21 5
59 4 22 5
59 5 19 5
59 5 20 5
59 5 21 5
59 5 22 5
59 5 23 5
59 6 18 5
59 6 19 5
59 6 20 5
59 6 21 5
59 6 22 5
59 6 23 5
59 6 24 5
59 7 17 5
59 7 18 5
59 7 19 5
59 7 20 5
59 7 22 5
59 7 23 5
59 7 24 5
59 7 25 5
59 8 18 5
59 8 19 5
59 8 20 5
59 8 21 5
59 8 22 5
59 8 23 5
59 8 24 5
59 9 19 5
59 9 20 5
59 9 21 5
59 9 22 5
59 9 23 5
59 10 20 5
59 10 21 5
59 10 22 5
59 11 21 6
60 3 21 6
60 4 20 5
60 4 21 5
60 4 22 5
60 5 19 5
60 5 20 5
60 5 21 5
60 5 22 5
60 5 23 5
60 6 18 5
60 6 19 5
60 6 20 5
60 6 21 5
60 6 22 5
60 6 23 5
60 6 24 5
60 7 17 5
60 7 18 5
60 7 19 5
60 7 20 5
60 7 22 5
60 7 23 5
60 7 24 5
60 7 25 5
60 8 18 5
60 8 19 5
60 8 20 5
60 8 21 5
60 8 22 5
60 8 23 5
60 8 24 5
60 9 19 5
60 9 20 5
60 9 21 5
60 9 22 5
60 9 23 5
60 10 20 5
60 10 21 5
60 10 22 5
60 11 21 6
61 3 21 6
61 4 20 5
61 4 21 5
61 4 22 5
61 5 19 5
61 5 20 5
61 5 21 5
61 5 22 5
61 5 23 5
61 6 18 5
61 6 19 5
61 6 20 5
61 6 21 5
61 6 22 5
61 6 23 5
61 6 24 5
61 7 17 5
61 7 18 5
61 7 19 5
61 7 20 5
61 7 22 5
61 7 23 5
61 7 24 5
61 7 25 5
61 8 18 5
61 8 19 5
61 8 20 5
61 8 21 5
61 8 22 5
61 8 23 5
61 8 24 5
61 9 19 5
61 9 20 5
61 9 21 5
61 9 22 5
61 9 23 5
61 10 20 5
61 10 21 5
61 10 22 5
61 11 21 6
62 3 21 6
62 4 20 5
62 4 21 5
62 4 22 5
62 5 19 5
62 5 20 5
62 5 21 5
62 5 22 5
62 5 23 5
62 6 18 5
62 6 19 5
62 6 20 5
62 6 21 5
62 6 22 5
62 6 23 5
62 6 24 5
62 7 17 5
62 7 18 5
62 7 19 5
62 7 20 5
62 7 22 5
62 7 23 5
62 7 24 5
62 7 25 5
62 8 18 5
62 8 19 5
62 8 20 5
62 8 21 5
62 8 22 5
62 8 23 5
62 8 24 5
62 9 19 5
62 9 20 5
62 9 21 5
62 9 22 5
62 9 23 5
62 10 20 5
62 10 21 5
62 10 22 5
62 11 21 6
63 3 21 6
63 4 20 5
63 4 21 5
63 4 22 5
63 5 19 5
63 5 20 5
63 5 21 5
63 5 22 5
63 5 23 5
63 6 18 5
63 6 19 5
63 6 20 5
63 6 21 5
63 6 22 5
63 6 23 5
63 6 24 5
63 7 17 5
63 7 18 5
63 7 19 5
63 7 20 5
63 7 22 5
63 7 23 5
63 7 24 5
63 7 25 5
63 8 18 5
63 8 19 5
63 8 20 5
63 8 21 5
63 8 22 5
63 8 23 5
63 8 24 5
63 9 19 5
63 9 20 5
63 9 21 5
63 9 22 5
63 9 23 5
63 10 20 5
63 10 21 5
63 10 22 5
63 11 21 6
64 3 21 6
64 4 20 5
64 4 21 5
64 4 22 5
64 5 19 5
64 5 20 5
64 5 21 5
64 5 22 5
64 5 23 5
64 6 18 5
64 6 19 5
64 6 20 5
64 6 21 5
64 6 22 5
64 6 23 5
64 6 24 5
64 7 17 5
64 7 18 5
64 7 19 5
64 7 20 5
64 7 22 5
64 7 23 5
64 7 24 5
64 7 25 5
64 8 18 5
64 8 19 5
64 8 20 5
64 8 21 5
64 8 22 5
64 8 23 5
64 8 24 5
64 9 19 5
64 9 20 5
64 9 21 5
64 9 22 5
64 9 23 5
64 10 20 5
64 10 21 5
64 10 22 5
64 11 21 6
65 3 21 6
65 4 20 5
65 4 21 5
65 4 22 5
65 5 19 5
65 5 20 5
65 5 21 5
65 5 22 5
65 5 23 5
65 6 18 5
65 6 19 5
65 6 20 5
65 6 21 5
65 6 22 5
65 6 23 5
65 6 24 5
65 7 17 5
65 7 18 5
65 7 19 5
65 7 20 5
65 7 22 5
65 7 23 5
65 7 24 5
65 7 25 5
65 8 18 5
65 8 19 5
65 8 20 5
65 8 21 5
65 8 22 5
65 8 23 5
65 8 24 5
65 9 19 5
65 9 20 5
65 9 21 5
65 9 22 5
65 9 23 5
65 10 20 5
65 10 21 5
65 10 22 5
65 11 21 6
66 3 21 6
66 4 20 5
66 4 21 5
66 4 22 5
66 5 19 5
66 5 20 5
66 5 21 5
66 5 22 5
66 5 23 5
66 6 18 5
66 6 19 5
66 6 20 5
66 6 21 5
66 6 22 5
66 6 23 5
66 6 24 5
66 7 17 5
66 7 18 5
66 7 19 5
66 7 20 5
66 7 22 5
66 7 23 5
66 7 24 5
66 7 25 5
66 8 18 5
66 8 19 5
66 8 20 5
66 8 21 5
66 8 22 5
66 8 23 5
66 8 24 5
66 9 19 5
66 9 20 5
66 9 21 5
66 9 22 5
66 9 23 5
66 10 20 5
66 10 21 5
66 10 22 5
66 11 21 6
67 3 21 6
67 4 20 5
67 4 21 5
67 4 22 5
67 5 19 5
67 5 20 5
67 5 21 5
67 5 22 5
67 5 23 5
67 6 18 5
67 6 19 5
67 6 20 5
67 6 21 5
67 6 23 5
67 6 24 5
67 7 16 5
67 7 17 5
67 7 18 5
67 7 19 5
67 7 20 5
67 7 23 5
67 7 24 5
67 7 25 5
67 7 26 5
67 8 18 5
67 8 19 5
67 8 20 5
67 8 21 5
67 8 23 5
67 8 24 5
67 9 19 5
67 9 20 5
67 9 21 5
67 9 22 5
67 9 23 5
67 10 20 5
67 10 21 5
67 10 22 5
67 11 21 6
68 3 21 6
68 4 20 5
68 4 21 5
68 4 22 5
68 5 19 5
68 5 20 5
68 5 21 5
68 5 22 5
68 5 23 5
68 6 17 5
68 6 18 5
68 6 19 5
68 6 20 5
68 6 21 5
68 6 22 5
68 6 23 5
68 6 24 5
68 6 25 5
68 7 16 5
68 7 17 5
68 7 18 5
68 7 19 5
68 7 20 5
68 7 23 5
68 7 24 5
68 7 25 5
68 7 26 5
68 8 17 5
68 8 18 5
68 8 19 5
68 8 20 5
68 8 21 5
68 8 22 5
68 8 23 5
68 8 24 5
68 8 25 5
68 9 19 5
68 9 20 5
68 9 21 5
68 9 22 5
68 9 23 5
68 10 20 5
68 10 21 5
68 10 22 5
68 11 21 6
69 3 21 6
69 4 20 5
69 4 21 5
69 4 22 5
69 5 18 5
69 5 19 5
69 5 20 5
69 5 21 5
69 5 22 5
69 5 23 5
69 5 24 5
69 6 17 5
69 6 18 5
69 6 19 5
69 6 20 5
69 6 21 5
69 6 22 5
69 6 23 5
69 6 24 5
69 6 25 5
69 7 16 5
69 7 17 5
69 7 18 5
69 7 19 5
69 7 20 5
69 7 22 5
69 7 23 5
69 7 24 5
69 7 25 5
69 7 26 5
69 8 17 5
69 8 18 5
69 8 19 5
69 8 20 5
69 8 21 5
69 8 22 5
69 8 23 5
69 8 24 5
69 8 25 5
69 9 18 5
69 9 19 5
69 9 20 5
69 9 21 5
69 9 22 5
69 9 23 5
69 9 24 5
69 10 20 5
69 10 21 5
69 10 22 5
69 11 21 6
70 3 21 6
70 4 20 5
70 4 21 5
70 4 22 5
70 5 18 5
70 5 19 5
70 5 20 5
70 5 21 5
70 5 22 5
70 5 23 5
70 5 24 5
70 6 17 5
70 6 18 5
70 6 19 5
70 6 20 5
70 6 21 5
70 6 22 5
70 6 23 5
70 6 24 5
70 6 25 5
70 7 16 5
70 7 17 5
70 7 18 5
70 7 19 5
70 7 20 5
70 7 22 5
70 7 23 5
70 7 24 5
70 7 25 5
70 7 26 5
70 8 17 5
70 8 18 5
70 8 19 5
70 8 20 5
70 8 21 5
70 8 22 5
70 8 23 5
70 8 24 5
70 8 25 5
70 9 18 5
70 9 19 5
70 9 20 5
70 9 21 5
70 9 22 5
70 9 23 5
70 9 24 5
70 10 20 5
70 10 21 5
70 10 22 5
70 11 21 6
71 3 21 6
71 4 20 5
71 4 21 5
71 4 22 5
71 5 18 5
71 5 19 5
71 5 20 5
71 5 21 5
71 5 22 5
71 5 23 5
71 5 24 5
71 6 17 5
71 6 18 5
71 6 19 5
71 6 20 5
71 6 21 5
71 6 22 5
71 6 23 5
71 6 24 5
71 6 25 5
71 7 16 5
71 7 17 5
71 7 18 5
71 7 19 5
71 7 22 5
71 7 23 5
71 7 24 5
71 7 25 5
71 7 26 5
71 8 17 5
71 8 18 5
71 8 19 5
71 8 20 5
71 8 21 5
71 8 22 5
71 8 23 5
71 8 24 5
71 8 25 5
71 9 18 5
71 9 19 5
71 9 20 5
71 9 21 5
71 9 22 5
71 9 23 5
71 9 24 5
71 10 20 5
71 10 21 5
71 10 22 5
71 11 21 6
72 3 21 6
72 4 19 5
72 4 20 5
72 4 21 5
72 4 22 5
72 4 23 5
72 5 18 5
72 5 19 5
72 5 20 5
72 5 21 5
72 5 22 5
72 5 23 5
72 5 24 5
72 6 17 5
72 6 18 5
72 6 19 5
72 6 22 5
72 6 23 5
72 6 24 5
72 6 25 5
72 7 16 5
72 7 17 5
72 7 18 5
72 7 23 5
72 7 24 5
72 7 25 5
72 7 26 5
72 8 17 5
72 8 18 5
72 8 19 5
72 8 22 5
72 8 23 5
72 8 24 5
72 8 25 5
72 9 18 5
72 9 19 5
72 9 20 5
72 9 21 5
72 9 22 5
72 9 23 5
72 9 24 5
72 10 19 5
72 10 20 5
72 10 21 5
72 10 22 5
72 10 23 5
72 11 21 6
73 3 21 6
73 4 19 5
73 4 20 5
73 4 21 5
73 4 22 5
73 4 23 5
73 5 18 5
73 5 19 5
73 5 20 5
73 5 21 5
73 5 22 5
73 5 23 5
73 5 24 5
73 6 17 5
73 6 18 5
73 6 19 5
73 6 20 5
73 6 21 5
73 6 22 5
73 6 23 5
73 6 24 5
73 6 25 5
73 7 16 5
73 7 17 5
73 7 18 5
73 7 19 5
73 7 23 5
73 7 24 5
73 7 25 5
73 7 26 5
73 8 17 5
73 8 18 5
73 8 19 5
73 8 20 5
73 8 21 5
73 8 22 5
73 8 23 5
73 8 24 5
73 8 25 5
73 9 18 5
73 9 19 5
73 9 20 5
73 9 21 5
73 9 22 5
73 9 23 5
73 9 24 5
73 10 19 5
73 10 20 5
73 10 21 5
73 10 22 5
73 10 23 5
73 11 21 6
74 3 21 6
74 4 19 5
74 4 20 5
74 4 21 5
74 4 22 5
74 4 23 5
74 5 18 5
74 5 19 5
74 5 20 5
74 5 21 5
74 5 22 5
74 5 23 5
74 5 24 5
74 6 17 5
74 6 18 5
74 6 19 5
74 6 20 5
74 6 21 5
74 6 23 5
74 6 24 5
74 6 25 5
74 7 16 5
74 7 17 5
74 7 18 5
74 7 19 5
74 7 23 5
74 7 24 5
74 7 25 5
74 7 26 5
74 8 17 5
74 8 18 5
74 8 19 5
74 8 20 5
74 8 21 5
74 8 23 5
74 8 24 5
74 8 25 5
74 9 18 5
74 9 19 5
74 9 20 5
74 9 21 5
74 9 22 5
74 9 23 5
74 9 24 5
74 10 19 5
74 10 20 5
74 10 21 5
74 10 22 5
74 10 23 5
74 11 21 6
75 3 21 6
75 4 19 5
75 4 20 5
75 4 21 5
75 4 22 5
75 4 23 5
75 5 18 5
75 5 19 5
75 5 20 5
75 5 21 5
75 5 22 5
75 5 23 5
75 5 24 5
75 6 17 5
75 6 18 5
75 6 19 5
75 6 20 5
75 6 21 5
75 6 22 5
75 6 23 5
75 6 24 5
75 6 25 5
75 7 15 5
75 7 16 5
75 7 17 5
75 7 18 5
75 7 19 5
75 7 23 5
75 7 24 5
75 7 25 5
75 7 26 5
75 7 27 5
75 8 17 5
75 8 18 5
75 8 19 5
75 8 20 5
75 8 21 5
75 8 22 5
75 8 23 5
75 8 24 5
75 8 25 5
75 9 18 5
75 9 19 5
75 9 20 5
75 9 21 5
75 9 22 5
75 9 23 5
75 9 24 5
75 10 19 5
75 10 20 5
75 10 21 5
75 10 22 5
75 10 23 5
75 11 21 6
76 3 21 6
76 4 19 5
76 4 20 5
76 4 21 5
76 4 22 5
76 4 23 5
76 5 18 5
76 5 19 5
76 5 20 5
76 5 21 5
76 5 22 5
76 5 23 5
76 5 24 5
76 6 16 5
76 6 17 5
76 6 18 5
76 6 22 5
76 6 23 5
76 6 24 5
76 6 25 5
76 6 26 5
76 7 15 5
76 7 16 5
76 7 17 5
76 7 18 5
76 7 23 5
76 7 24 5
76 7 25 5
76 7 26 5
76 7 27 5
76 8 16 5
76 8 17 5
76 8 18 5
76 8 22 5
76 8 23 5
76 8 24 5
76 8 25 5
76 8 26 5
76 9 18 5
76 9 19 5
76 9 20 5
76 9 21 5
76 9 22 5
76 9 23 5
76 9 24 5
76 10 19 5
76 10 20 5
76 10 21 5
76 10 22 5
76 10 23 5
76 11 21 6
77 3 21 6
77 4 19 5
77 4 20 5
77 4 21 5
77 4 22 5
77 4 23 5
77 5 17 5
77 5 18 5
77 5 19 5
77 5 20 5
77 5 21 5
77 5 22 5
77 5 23 5
77 5 24 5
77 5 25 5
77 6 16 5
77 6 17 5
77 6 18 5
77 6 22 5
77 6 23 5
77 6 24 5
77 6 25 5
77 6 26 5
77 7 15 5
77 7 16 5
77 7 17 5
77 7 18 5
77 7 23 5
77 7 24 5
77 7 25 5
77 7 26 5
77 7 27 5
77 8 16 5
77 8 17 5
77 8 18 5
77 8 22 5
77 8 23 5
77 8 24 5
77 8 25 5
77 8 26 5
77 9 17 5
77 9 18 5
77 9 19 5
77 9 20 5
77 9 21 5
77 9 22 5
77 9 23 5
77 9 24 5
77 9 25 5
77 10 19 5
77 10 20 5
77 10 21 5
77 10 22 5
77 10 23 5
77 11 21 6
78 3 21 6
78 4 19 5
78 4 20 5
78 4 21 5
78 4 22 5
78 4 23 5
78 5 17 5
78 5 18 5
78 5 19 5
78 5 20 5
78 5 21 5
78 5 22 5
78 5 23 5
78 5 24 5
78 5 25 5
78 6 16 5
78 6 17 5
78 6 18 5
78 6 19 5
78 6 20 5
78 6 23 5
78 6 24 5
78 6 25 5
78 6 26 5
78 7 15 5
78 7 16 5
78 7 17 5
78 7 18 5
78 7 24 5
78 7 25 5
78 7 26 5
78 7 27 5
78 8 16 5
78 8 17 5
78 8 18 5
78 8 19 5
78 8 20 5
78 8 23 5
78 8 24 5
78 8 25 5
78 8 26 5
78 9 17 5
78 9 18 5
78 9 19 5
78 9 20 5
78 9 21 5
78 9 22 5
78 9 23 5
78 9 24 5
78 9 25 5
78 10 19 5
78 10 20 5
78 10 21 5
78 10 22 5
78 10 23 5
78 11 21 6
79 3 21 6
79 4 19 5
79 4 20 5
79 4 21 5
79 4 22 5
79 4 23 5
79 5 17 5
79 5 18 5
79 5 19 5
79 5 20 5
79 5 21 5
79 5 22 5
79 5 23 5
79 5 24 5
79 5 25 5
79 6 16 5
79 6 17 5
79 6 18 5
79 6 19 5
79 6 20 5
79 6 21 5
79 6 23 5
79 6 24 5
79 6 25 5
79 6 26 5
79 7 14 5
79 7 15 5
79 7 16 5
79 7 17 5
79 7 18 5
79 7 24 5
79 7 25 5
79 7 26 5
79 7 27 5
79 7 28 5
79 8 16 5
79 8 17 5
79 8 18 5
79 8 19 5
79 8 20 5
79 8 21 5
79 8 23 5
79 8 24 5
79 8 25 5
79 8 26 5
79 9 17 5
79 9 18 5
79 9 19 5
79 9 20 5
79 9 21 5
79 9 22 5
79 9 23 5
79 9 24 5
79 9 25 5
79 10 19 5
79 10 20 5
79 10 21 5
79 10 22 5
79 10 23 5
79 11 21 6
80 3 21 6
80 4 18 5
80 4 19 5
80 4 20 5
80 4 21 5
80 4 22 5
80 4 23 5
80 4 24 5
80 5 17 5
80 5 18 5
80 5 19 5
80 5 20 5
80 5 21 5
80 5 22 5
80 5 23 5
80 5 24 5
80 5 25 5
80 6 15 5
80 6 16 5
80 6 17 5
80 6 18 5
80 6 19 5
80 6 20 5
80 6 21 5
80 6 22 5
80 6 23 5
80 6 24 5
80 6 25 5
80 6 26 5
80 6 27 5
80 7 14 5
80 7 15 5
80 7 16 5
80 7 17 5
80 7 18 5
80 7 24 5
80 7 25 5
80 7 26 5
80 7 27 5
80 7 28 5
80 8 15 5
80 8 16 5
80 8 17 5
80 8 18 5
80 8 19 5
80 8 20 5
80 8 21 5
80 8 22 5
80 8 23 5
80 8 24 5
80 8 25 5
80 8 26 5
80 8 27 5
80 9 17 5
80 9 18 5
80 9 19 5
80 9 20 5
80 9 21 5
80 9 22 5
80 9 23 5
80 9 24 5
80 9 25 5
80 10 18 5
80 10 19 5
80 10 20 5
80 10 21 5
80 10 22 5
80 10 23 5
80 10 24 5
80 11 21 6
81 3 21 6
81 4 18 5
81 4 19 5
81 4 20 5
81 4 21 5
81 4 22 5
81 4 23 6
81 4 24 5
81 5 16 5
81 5 17 5
81 5 18 5
81 5 19 5
81 5 20 5
81 5 21 5
81 5 22 5
81 5 23 5
81 5 24 5
81 5 25 5
81 5 26 5
81 6 15 5
81 6 16 5
81 6 17 5
81 6 18 5
81 6 19 5
81 6 20 5
81 6 21 5
81 6 22 5
81 6 23 5
81 6 24 5
81 6 25 5
81 6 26 5
81 6 27 5
81 7 14 5
81 7 15 5
81 7 16 5
81 7 17 5
81 7 18 5
81 7 24 5
81 7 25 5
81 7 26 5
81 7 27 5
81 7 28 5
81 8 15 5
81 8 16 5
81 8 17 5
81 8 18 5
81 8 19 5
81 8 20 5
81 8 21 5
81 8 22 5
81 8 23 5
81 8 24 5
81 8 25 5
81 8 26 5
81 8 27 5
81 9 16 5
81 9 17 5
81 9 18 5
81 9 19 5
81 9 20 5
81 9 21 5
81 9 22 5
81 9 23 5
81 9 24 5
81 9 25 5
81 9 26 5
81 10 18 5
81 10 19 5
81 10 20 5
81 10 21 5
81 10 22 5
81 10 23 6
81 10 24 5
81 11 21 6
82 3 21 6
82 4 18 6
82 4 19 5
82 4 20 6
82 4 21 5
82 4 22 6
82 4 23 5
82 4 24 5
82 5 16 5
82 5 17 5
82 5 18 5
82 5 19 5
82 5 20 5
82 5 21 5
82 5 22 5
82 5 23 5
82 5 24 5
82 5 25 5
82 5 26 5
82 6 15 5
82 6 16 5
82 6 17 5
82 6 18 5
82 6 19 5
82 6 20 5
82 6 21 5
82 6 22 5
82 6 23 5
82 6 24 5
82 6 25 5
82 6 26 5
82 6 27 5
82 7 14 5
82 7 15 5
82 7 16 5
82 7 17 5
82 7 24 5
82 7 25 5
82 7 26 5
82 7 27 5
82 7 28 5
82 8 15 5
82 8 16 5
82 8 17 5
82 8 18 5
82 8 19 5
82 8 20 5
82 8 21 5
82 8 22 5
82 8 23 5
82 8 24 5
82 8 25 5
82 8 26 5
82 8 27 5
82 9 16 5
82 9 17 5
82 9 18 5
82 9 19 5
82 9 20 5
82 9 21 5
82 9 22 5
82 9 23 5
82 9 24 5
82 9 25 5
82 9 26 5
82 10 18 6
82 10 19 5
82 10 20 6
82 10 21 5
82 10 22 6
82 10 23 5
82 10 24 5
82 11 21 6
83 3 21 6
83 4 17 5
83 4 18 5
83 4 19 6
83 4 20 6
83 4 21 5
83 4 22 6
83 4 23 6
83 4 24 5
83 4 25 5
83 5 16 5
83 5 17 5
83 5 18 5
83 5 19 5
83 5 20 5
83 5 21 5
83 5 22 5
83 5 23 5
83 5 24 5
83 5 25 5
83 5 26 5
83 6 14 5
83 6 15 5
83 6 16 5
83 6 17 5
83 6 18 5
83 6 19 5
83 6 20 5
83 6 23 5
83 6 24 5
83 6 25 5
83 6 26 5
83 6 27 5
83 6 28 5
83 7 13 5
83 7 14 5
83 7 15 5
83 7 16 5
83 7 17 5
83 7 24 5
83 7 25 5
83 7 26 5
83 7 27 5
83 7 28 5
83 7 29 5
83 8 14 5
83 8 15 5
83 8 16 5
83 8 17 5
83 8 18 5
83 8 19 5
83 8 20 5
83 8 23 5
83 8 24 5
83 8 25 5
83 8 26 5
83 8 27 5
83 8 28 5
83 9 16 5
83 9 17 5
83 9 18 5
83 9 19 5
83 9 20 5
83 9 21 5
83 9 22 5
83 9 23 5
83 9 24 5
83 9 25 5
83 9 26 5
83 10 17 5
83 10 18 5
83 10 19 6
83 10 20 6
83 10 21 5
83 10 22 6
83 10 23 6
83 10 24 5
83 10 25 5
83 11 21 6
84 3 17 6
84 3 18 6
84 3 19 6
84 3 20 6
84 3 21 6
84 3 22 6
84 3 23 6
84 3 24 6
84 3 25 6
84 4 15 6
84 4 16 6
84 4 17 5
84 4 18 5
84 4 19 5
84 4 20 5
84 4 21 5
84 4 22 5
84 4 23 5
84 4 24 5
84 4 25 5
84 4 26 6
84 4 27 6
84 5 14 6
84 5 15 5
84 5 16 5
84 5 17 5
84 5 18 5
84 5 19 5
84 5 20 5
84 5 21 5
84 5 22 5
84 5 23 5
84 5 24 5
84 5 25 5
84 5 26 5
84 5 27 5
84 5 28 6
84 6 13 6
84 6 14 5
84 6 15 5
84 6 16 5
84 6 17 5
84 6 18 5
84 6 19 5
84 6 22 5
84 6 23 5
84 6 24 5
84 6 25 5
84 6 26 5
84 6 27 5
84 6 28 5
84 6 29 6
84 7 12 6
84 7 13 5
84 7 14 5
84 7 15 5
84 7 16 5
84 7 17 5
84 7 25 5
84 7 26 5
84 7 27 5
84 7 28 5
84 7 29 5
84 7 30 6
84 8 13 6
84 8 14 5
84 8 15 5
84 8 16 5
84 8 17 5
84 8 18 5
84 8 19 5
84 8 22 5
84 8 23 5
84 8 24 5
84 8 25 5
84 8 26 5
84 8 27 5
84 8 28 5
84 8 29 6
84 9 14 6
84 9 15 5
84 9 16 5
84 9 17 5
84 9 18 5
84 9 19 5
84 9 20 5
84 9 21 5
84 9 22 5
84 9 23 5
84 9 24 5
84 9 25 5
84 9 26 5
84 9 27 5
84 9 28 6
84 10 15 6
84 10 16 6
84 10 17 5
84 10 18 5
84 10 19 5
84 10 20 5
84 10 21 5
84 10 22 5
84 10 23 5
84 10 24 5
84 10 25 5
84 10 26 6
84 10 27 6
84 11 17 6
84 11 18 6
84 11 19 6
84 11 20 6
84 11 21 6
84 11 22 6
84 11 23 6
84 11 24 6
84 11 25 6
85 3 21 6
85 4 18 5
85 4 19 5
85 4 20 6
85 4 21 5
85 4 22 6
85 4 23 5
85 4 24 5
85 5 16 5
85 5 17 5
85 5 18 5
85 5 19 5
85 5 20 5
85 5 21 5
85 5 22 5
85 5 23 5
85 5 24 5
85 5 25 5
85 5 26 5
85 6 14 5
85 6 15 5
85 6 16 5
85 6 17 5
85 6 18 5
85 6 19 5
85 6 20 5
85 6 21 5
85 6 22 5
85 6 23 5
85 6 24 5
85 6 25 5
85 6 26 5
85 6 27 5
85 6 28 5
85 7 13 5
85 7 14 5
85 7 15 5
85 7 16 5
85 7 25 5
85 7 26 5
85 7 27 5
85 7 28 5
85 7 29 5
85 8 14 5
85 8 15 5
85 8 16 5
85 8 17 5
85 8 18 5
85 8 19 5
85 8 20 5
85 8 21 5
85 8 22 5
85 8 23 5
85 8 24 5
85 8 25 5
85 8 26 5
85 8 27 5
85 8 28 5
85 9 16 5
85 9 17 5
85 9 18 5
85 9 19 5
85 9 20 5
85 9 21 5
85 9 22 5
85 9 23 5
85 9 24 5
85 9 25 5
85 9 26 5
85 10 18 5
85 10 19 5
85 10 20 6
85 10 21 5
85 10 22 6
85 10 23 5
85 10 24 5
85 11 21 6
86 3 21 6
86 4 18 5
86 4 19 5
86 4 20 5
86 4 21 5
86 4 22 5
86 4 23 6
86 5 17 5
86 5 18 5
86 5 19 5
86 5 20 5
86 5 21 5
86 5 22 5
86 5 23 5
86 5 24 5
86 5 25 5
86 6 15 5
86 6 16 5
86 6 17 5
86 6 18 5
86 6 19 5
86 6 20 5
86 6 21 5
86 6 22 5
86 6 23 5
86 6 24 5
86 6 25 5
86 6 26 5
86 6 27 5
86 7 14 5
86 7 15 5
86 7 16 5
86 7 17 5
86 7 24 5
86 7 25 5
86 7 26 5
86 7 27 5
86 7 28 5
86 8 15 5
86 8 16 5
86 8 17 5
86 8 18 5
86 8 19 5
86 8 20 5
86 8 21 5
86 8 22 5
86 8 23 5
86 8 24 5
86 8 25 5
86 8 26 5
86 8 27 5
86 9 17 5
86 9 18 5
86 9 19 5
86 9 20 5
86 9 21 5
86 9 22 5
86 9 23 5
86 9 24 5
86 9 25 5
86 10 18 5
86 10 19 5
86 10 20 5
86 10 21 5
86 10 22 5
86 10 23 6
86 11 21 6
87 3 21 6
87 4 19 6
87 4 20 5
87 4 21 5
87 4 22 5
87 4 23 5
87 5 17 5
87 5 18 5
87 5 19 5
87 5 20 5
87 5 21 5
87 5 22 5
87 5 23 5
87 5 24 5
87 5 25 5
87 6 16 5
87 6 17 5
87 6 18 5
87 6 19 5
87 6 20 5
87 6 21 5
87 6 22 5
87 6 23 5
87 6 24 5
87 6 25 5
87 6 26 5
87 7 15 5
87 7 16 5
87 7 17 5
87 7 18 5
87 7 23 5
87 7 24 5
87 7 25 5
87 7 26 5
87 7 27 5
87 8 16 5
87 8 17 5
87 8 18 5
87 8 19 5
87 8 20 5
87 8 21 5
87 8 22 5
87 8 23 5
87 8 24 5
87 8 25 5
87 8 26 5
87 9 17 5
87 9 18 5
87 9 19 5
87 9 20 5
87 9 21 5
87 9 22 5
87 9 23 5
87 9 24 5
87 9 25 5
87 10 19 6
87 10 20 5
87 10 21 5
87 10 22 5
87 10 23 5
87 11 21 6
88 3 21 6
88 4 20 5
88 4 21 5
88 4 22 5
88 5 18 5
88 5 19 5
88 5 20 5
88 5 21 5
88 5 22 5
88 5 23 5
88 5 24 5
88 6 16 5
88 6 17 5
88 6 18 5
88 6 19 5
88 6 20 5
88 6 21 5
88 6 22 5
88 6 23 5
88 6 24 5
88 6 25 5
88 6 26 5
88 7 15 5
88 7 16 5
88 7 17 5
88 7 18 5
88 7 23 5
88 7 24 5
88 7 25 5
88 7 26 5
88 7 27 5
88 8 16 5
88 8 17 5
88 8 18 5
88 8 19 5
88 8 20 5
88 8 21 5
88 8 22 5
88 8 23 5
88 8 24 5
88 8 25 5
88 8 26 5
88 9 18 5
88 9 19 5
88 9 20 5
88 9 21 5
88 9 22 5
88 9 23 5
88 9 24 5
88 10 20 5
88 10 21 5
88 10 22 5
88 11 21 6
89 3 21 6
89 4 20 5
89 4 21 5
89 4 22 5
89 5 18 5
89 5 19 5
89 5 20 5
89 5 21 5
89 5 22 5
89 5 23 5
89 5 24 5
89 6 17 5
89 6 18 5
89 6 19 5
89 6 20 5
89 6 21 5
89 6 22 5
89 6 23 5
89 6 24 5
89 6 25 5
89 7 16 5
89 7 17 5
89 7 18 5
89 7 19 5
89 7 20 5
89 7 21 5
89 7 23 5
89 7 24 5
89 7 25 5
89 7 26 5
89 8 17 5
89 8 18 5
89 8 19 5
89 8 20 5
89 8 21 5
89 8 22 5
89 8 23 5
89 8 24 5
89 8 25 5
89 9 18 5
89 9 19 5
89 9 20 5
89 9 21 5
89 9 22 5
89 9 23 5
89 9 24 5
89 10 20 5
89 10 21 5
89 10 22 5
89 11 21 6
90 3 21 6
90 4 21 5
90 5 19 5
90 5 20 5
90 5 21 5
90 5 22 5
90 5 23 5
90 6 17 5
90 6 18 5
90 6 19 5
90 6 20 5
90 6 21 5
90 6 22 5
90 6 23 5
90 6 24 5
90 6 25 5
90 7 16 5
90 7 17 5
90 7 18 5
90 7 19 5
90 7 20 5
90 7 21 5
90 7 22 5
90 7 23 5
90 7 24 5
90 7 25 5
90 7 26 5
90 8 17 5
90 8 18 5
90 8 19 5
90 8 20 5
90 8 21 5
90 8 22 5
90 8 23 5
90 8 24 5
90 8 25 5
90 9 19 5
90 9 20 5
90 9 21 5
90 9 22 5
90 9 23 5
90 10 21 5
90 11 21 6
91 4 21 6
91 5 19 5
91 5 20 5
91 5 21 5
91 5 22 5
91 5 23 5
91 6 18 5
91 6 19 5
91 6 20 5
91 6 21 5
91 6 22 5
91 6 23 5
91 6 24 5
91 7 17 5
91 7 18 5
91 7 19 5
91 7 20 5
91 7 21 5
91 7 22 5
91 7 23 5
91 7 24 5
91 7 25 5
91 8 18 5
91 8 19 5
91 8 20 5
91 8 21 5
91 8 22 5
91 8 23 5
91 8 24 5
91 9 19 5
91 9 20 5
91 9 21 5
91 9 22 5
91 9 23 5
91 10 21 6
92 4 21 6
92 5 20 5
92 5 21 5
92 5 22 5
92 6 18 5
92 6 19 5
92 6 20 5
92 6 21 5
92 6 22 5
92 6 23 5
92 6 24 5
92 7 17 5
92 7 18 5
92 7 19 5
92 7 20 5
92 7 21 5
92 7 22 5
92 7 23 5
92 7 24 5
92 7 25 5
92 8 18 5
92 8 19 5
92 8 20 5
92 8 21 5
92 8 22 5
92 8 23 5
92 8 24 5
92 9 20 5
92 9 21 5
92 9 22 5
92 10 21 6
93 4 21 6
93 5 20 5
93 5 21 5
93 5 22 5
93 6 19 5
93 6 20 5
93 6 21 5
93 6 22 5
93 6 23 5
93 7 18 5
93 7 19 5
93 7 20 5
93 7 21 5
93 7 22 5
93 7 23 5
93 7 24 5
93 8 19 5
93 8 20 5
93 8 21 5
93 8 22 5
93 8 23 5
93 9 20 5
93 9 21 5
93 9 22 5
93 10 21 6
94 4 21 6
94 5 21 5
94 6 19 5
94 6 20 5
94 6 21 5
94 6 22 5
94 6 23 5
94 7 18 5
94 7 19 5
94 7 20 5
94 7 21 5
94 7 22 5
94 7 23 5
94 7 24 5
94 8 19 5
94 8 20 5
94 8 21 5
94 8 22 5
94 8 23 5
94 9 21 5
94 10 21 6
95 5 21 6
95 6 20 5
95 6 21 5
95 6 22 5
95 7 19 5
95 7 20 5
95 7 21 5
95 7 22 5
95 7 23 5
95 8 20 5
95 8 21 5
95 8 22 5
95 9 21 6
96 5 21 6
96 6 20 5
96 6 21 6
96 6 22 5
96 7 19 5
96 7 20 5
96 7 21 5
96 7 22 5
96 7 23 5
96 8 20 5
96 8 21 6
96 8 22 5
96 9 21 6
97 6 21 6
97 7 20 5
97 7 21 5
97 7 22 5
97 8 21 6
98 6 21 6
98 7 20 5
98 7 21 5
98 7 22 5
98 8 21 6
99 7 21 6
